Workbook

Sheet วิธีใช้
B2: วิธีใช้แบบประเมินพฤติกรรมนักเรียน SDQ
B3: =ข้อมูล!C7 -> โรงเรียนเทศบาลท่าอิฐ อำเภอเมือง จังหวัดอุตรดิตถ์
B4: 1. ต้องมีแบบประเมินพฤติกรรม SDQ1 ฉบับนักเรียนประเมินตนเอง
C5: SDQ1 ฉบับนักเรียนประเมินตนเอง
C6: SDQ2 ฉบับครูประเมินนักเรียน
C7: SDQ3 ฉบับผู้ปกครองประเมินนักเรียน ที่ทำการประเมินเรียบร้อยแล้ว (ครบทั้ง 3 ชุด)
B8: 2. ที่ Sheet รายชื่อนักเรียน ให้พิมพ์รายชื่อนักเรียนและเลขประจำตัว ลงที่หน้านี้เท่านั้น
C9: ถ้ารายชื่อไม่ถึง 40 คน ให้ลบคอลั่มน์ที่ไม่ได้ใช้ทิ้ง (ให้ลบทุก Sheet)
B10: 3. ที่ Sheet ข้อมูล ให้แก้ไขเฉพาะกรอบสีฟ้า เท่านั้น
B11: 4. ที่ Sheet ประเมินตนเอง, ครูประเมิน, และผู้ปกครองประเมิน ให้พิมพ์เลข 1 (แทนเครื่องหมายถูก) ลงในช่องรายการประเมินตามข้อมูลที่ประเมินมาเท่านั้น เช่น
D14: รายการประเมิน
D15: ข้อที่ | E15: ไม่จริง | F15: ค่อนข้างจริง | G15: จริง
D16: 1 | E16: 1
D17: 2 | G17: 1
D18: 3 | F18: 1
D19: 4 | E19: 1
D20: 5 | F20: 1
B23: 5. ใน 1 ข้อ ให้พิมพ์เลข 1 เพียง 1 ครั้งเท่านั้น
B24: 6. ขณะที่ป้อนข้อมูลโปรแกรมจะทำการรวมผลไปตลอดเวลา ดังนั้นจะเห็นการเปลี่ยนแปลงของตัวเลขในช่องคะแนนรวมเรื่อย ๆ อีกทั้งจะทำการแปลผลไปในตัวเลย
B25: 7. ใน Sheet แปลผล และ สรุปรวม -- ไม่ต้องกรอกข้อมูลใด ๆ ทั้งสิ้น
B26: 8. ส่งไฟล์มาที่ SDQTHAITSCHOOL@gmail.com
A28: หมายเหตุ
C29: ก. โปรแกรมนี้จัดทำสำหรับนักเรียนมากที่สุด 40 คน ต่อ 1 ห้องเรียน
C30: ข. ถ้ารายชื่อไม่ถึง 40 คน ให้์ลบถวท่ี่ไม่ได้ใช้ทิ้งได้ (ให้ลบทุก Sheet)
C31: ค. ใช้ font TH Sarabun New ขนาด 14 P.
L33: กลุ่มงานระบบดูแลช่วยเหลือนักเรียน
L34: =ข้อมูล!C7 -> โรงเรียนเทศบาลท่าอิฐ อำเภอเมือง จังหวัดอุตรดิตถ์

Sheet รายชื่อ
A1: 1 | B1: เด็กชาย | C1: ณฐวัฒน์ | D1: ขวัญมุข
A2: 2 | B2: เด็กชาย | C2: นพธรรศ | D2: ปั่นจีด
A3: 3 | B3: เด็กชาย | C3: นภัทร | D3: เอมเทศ
A4: 4 | B4: เด็กชาย | C4: ภูมิพัฒน์ | D4: เต็งวิลัย
A5: 5 | B5: เด็กชาย | C5: ฑิติพัฒน์ | D5: เชตุทอง
A6: 6 | B6: เด็กชาย | C6: กฤษณพล | D6: สมศรี
A7: 7 | B7: เด็กชาย | C7: จักรภัทร | D7: วิเศษสุวรรณภูมิ
A8: 8 | B8: เด็กชาย | C8: จิรายุ | D8: บุญเนตร
A9: 9 | B9: เด็กชาย | C9: สรศักดิ์ | D9: เกิดสา
A10: 10 | B10: เด็กชาย | C10: ธีรภัทร | D10: ทวีชัยการ
A11: 11 | B11: เด็กชาย | C11: นัธทวัฒน์ | D11: เหล่าจันอัน
A12: 12 | B12: เด็กชาย | C12: พงศพัศ | D12: เกื้อเกตุ
... A27: 27 | B27: เด็กหญิง | C27: ยิ่งลักษณ์ | D27: ลักษณพิสุทธิ์
A28: 28
A29: 29
A30: 30
A31: 31
A32: 32
A33: 33
A34: 34
A35: 35
A36: 36
A37: 37
A38: 38
A39: 39
A40: 40

Sheet ข้อมูล
A1: แก้เฉพาะในกรอบสีฟ้า | B1: ระดับ | C1: ชั้นประถมศึกษาปีที่
B2: ชั้น | C2: 6/3
B3: จำนวนนักเรียนทั้งหมด | C3: 27 | D3: คน
B4: ปีการศึกษา | C4: 2568
B5: ครูที่ปรึกษา 1 | C5: นางสาวพอใจ สุขหา | D5: ถ้ามีคนเดียว ให้ใส่ชื่อที่ครูที่ปรึกษา 1 แล้้้วใส่เครื่องหมายลบ (-) ที่ช่องครูที่ปรึกษา 2
B6: ครูที่ปรึกษา 2 | C6: นางสาวพอใจ สุขหา
B7: โรงเรียน | C7: โรงเรียนเทศบาลท่าอิฐ อำเภอเมือง จังหวัดอุตรดิตถ์
A8: แก้เฉพาะในกรอบสีฟ้า
B10: ระดับประถม | C10: ชั้นประถมศึกษาปีที่
B11: ระดับมัธยม | C11: ชั้นมัธยมศึกษาปีที่

Sheet 01
A1: ผลการประเมินพฤติกรรมตนเอง (SDQ) | M1: ผลการประเมินพฤติกรรม ครูประเมินนักเรียน (SDQ) | Y1: ผลการประเมินพฤติกรรม ผู้ปกครองประเมินนักเรียน (SDQ)
A2: =ข้อมูล!C7 -> โรงเรียนเทศบาลท่าอิฐ อำเภอเมือง จังหวัดอุตรดิตถ์ | M2: =ข้อมูล!C7 -> โรงเรียนเทศบาลท่าอิฐ อำเภอเมือง จังหวัดอุตรดิตถ์ | Y2: โรงเรียนเทศบาลท่าอิฐ อำเภอเมือง จังหวัดอุตรดิตถ์
A3: ชื่อ-สกุล | B3: =รายชื่อ!B1 -> เด็กชาย | C3: =รายชื่อ!C1 -> ณฐวัฒน์ | D3: =รายชื่อ!D1 -> ขวัญมุข | K3: =รายชื่อ!A1 -> 1 | M3: ชื่อ-สกุล | N3: =รายชื่อ!B1 -> เด็กชาย | O3: =รายชื่อ!C1 -> ณฐวัฒน์ | P3: =รายชื่อ!D1 -> ขวัญมุข | W3: 1 | Y3: ชื่อ-สกุล | Z3: =รายชื่อ!B1 -> เด็กชาย | AA3: =รายชื่อ!C1 -> ณฐวัฒน์ | AB3: =รายชื่อ!D1 -> ขวัญมุข | AI3: 1
A4: SDQ1 | M4: SDQ2 | Y4: SDQ3
A5: รายการประเมินโดยนักเรียน | F5: คะแนน | K5: รวมคะแนนด้านอารมณ์ 10 คะแนน | M5: รายการประเมินโดยครู | R5: คะแนน | W5: รวมคะแนนด้านอารมณ์ 10 คะแนน | Y5: รายการประเมินโดยผู้ปกครอง | AD5: คะแนน | AI5: รวมคะแนนด้านอารมณ์ 10 คะแนน
A6: ข้อที่ | B6: ไม่จริง | C6: ค่อนข้างจริง | D6: จริง | F6: ไม่จริง | G6: ค่อนข้างจริง | H6: จริง | I6: รวม | K6: เกณฑ์ 0 - 5 ปกติ , 6 - 10 เสี่ยง/มีปัญหา | M6: ข้อที่ | N6: ไม่จริง | O6: ค่อนข้างจริง | P6: จริง | R6: ไม่จริง | S6: ค่อนข้างจริง | T6: จริง | U6: รวม | W6: เกณฑ์ 0 - 5 ปกติ , 6 - 10 เสี่ยง/มีปัญหา | Y6: ข้อที่ | Z6: ไม่จริง | AA6: ค่อนข้างจริง | AB6: จริง | AD6: ไม่จริง | AE6: ค่อนข้างจริง | AF6: จริง | AG6: รวม | AI6: เกณฑ์ 0 - 5 ปกติ , 6 - 10 เสี่ยง/มีปัญหา
A7: 1 | C7: 1 | F7: =B7*0 -> 0 | G7: =C7*1 -> 1 | H7: =D7*2 -> 0 | I7: =SUM(F7:F7) -> 0 | J7: =I9+I14+I19+I22+I30 -> 0 | K7: =J7 -> 0 | M7: 1 | P7: 1 | R7: =N7*0 -> 0 | S7: =O7*1 -> 0 | T7: =P7*2 -> 2 | U7: =SUM(R7:R7) -> 0 | V7: =U9+U14+U19+U22+U30 -> 0 | W7: =V7 -> 0 | Y7: 1 | AB7: 1 | AD7: =Z7*0 -> 0 | AE7: =AA7*1 -> 0 | AF7: =AB7*2 -> 2 | AG7: =SUM(AD7:AD7) -> 0 | AH7: =AG9+AG14+AG19+AG22+AG30 -> 0 | AI7: =AH7 -> 0
A8: 2 | C8: 1 | F8: =B8*0 -> 0 | G8: =C8*1 -> 1 | H8: =D8*2 -> 0 | I8: =SUM(F8:F8) -> 0 | M8: 2 | N8: 1 | R8: =N8*0 -> 0 | S8: =O8*1 -> 0 | T8: =P8*2 -> 0 | U8: =SUM(R8:R8) -> 0 | Y8: 2 | AA8: 1 | AD8: =Z8*0 -> 0 | AE8: =AA8*1 -> 1 | AF8: =AB8*2 -> 0 | AG8: =SUM(AD8:AD8) -> 0
A9: 3 | B9: 1 | F9: =B9*0 -> 0 | G9: =C9*1 -> 0 | H9: =D9*2 -> 0 | I9: =SUM(F9:F9) -> 0 | M9: 3 | P9: 1 | R9: =N9*0 -> 0 | S9: =O9*1 -> 0 | T9: =P9*2 -> 2 | U9: =SUM(R9:R9) -> 0 | Y9: 3 | Z9: 1 | AD9: =Z9*0 -> 0 | AE9: =AA9*1 -> 0 | AF9: =AB9*2 -> 0 | AG9: =SUM(AD9:AD9) -> 0
A10: 4 | C10: 2 | F10: =B10*0 -> 0 | G10: =C10*1 -> 2 | H10: =D10*2 -> 0 | I10: =SUM(F10:F10) -> 0 | K10: รวมคะแนนด้านความประพฤติ/เกเร 10 คะแนน | M10: 4 | O10: 1 | R10: =N10*0 -> 0 | S10: =O10*1 -> 1 | T10: =P10*2 -> 0 | U10: =SUM(R10:R10) -> 0 | W10: รวมคะแนนด้านความประพฤติ/เกเร 10 คะแนน | Y10: 4 | AB10: 1 | AD10: =Z10*0 -> 0 | AE10: =AA10*1 -> 0 | AF10: =AB10*2 -> 2 | AG10: =SUM(AD10:AD10) -> 0 | AI10: รวมคะแนนด้านความประพฤติ/เกเร 10 คะแนน
A11: 5 | B11: 1 | F11: =B11*0 -> 0 | G11: =C11*1 -> 0 | H11: =D11*2 -> 0 | I11: =SUM(F11:F11) -> 0 | K11: เกณฑ์ 0 - 4 ปกติ , 5 - 10 เสี่ยง/มีปัญหา | M11: 5 | N11: 1 | R11: =N11*0 -> 0 | S11: =O11*1 -> 0 | T11: =P11*2 -> 0 | U11: =SUM(R11:R11) -> 0 | W11: เกณฑ์ 0 - 4 ปกติ , 5 - 10 เสี่ยง/มีปัญหา | Y11: 5 | Z11: 1 | AD11: =Z11*0 -> 0 | AE11: =AA11*1 -> 0 | AF11: =AB11*2 -> 0 | AG11: =SUM(AD11:AD11) -> 0 | AI11: เกณฑ์ 0 - 4 ปกติ , 5 - 10 เสี่ยง/มีปัญหา
A12: 6 | C12: 1 | F12: =B12*0 -> 0 | G12: =C12*1 -> 1 | H12: =D12*2 -> 0 | I12: =SUM(F12:F12) -> 0 | J12: =I11+I13+I18+I24+I28 -> 4 | K12: =J12 -> 4 | M12: 6 | O12: 1 | R12: =N12*0 -> 0 | S12: =O12*1 -> 1 | T12: =P12*2 -> 0 | U12: =SUM(R12:R12) -> 0 | V12: =U11+U13+U18+U24+U28 -> 2 | W12: =V12 -> 2 | Y12: 6 | AA12: 1 | AD12: =Z12*0 -> 0 | AE12: =AA12*1 -> 1 | AF12: =AB12*2 -> 0 | AG12: =SUM(AD12:AD12) -> 0 | AH12: =AG11+AG13+AG18+AG24+AG28 -> 4 | AI12: =AH12 -> 4
A13: 7 | B13: 1 | F13: =B13*2 -> 2 | G13: =C13*1 -> 0 | H13: =D13*0 -> 0 | I13: =SUM(F13:F13) -> 2 | M13: 7 | P13: 1 | R13: =N13*2 -> 0 | S13: =O13*1 -> 0 | T13: =P13*0 -> 0 | U13: =SUM(R13:R13) -> 0 | Y13: 7 | Z13: 1 | AD13: =Z13*2 -> 2 | AE13: =AA13*1 -> 0 | AF13: =AB13*0 -> 0 | AG13: =SUM(AD13:AD13) -> 2
A14: 8 | C14: 1 | F14: =B14*0 -> 0 | G14: =C14*1 -> 1 | H14: =D14*2 -> 0 | I14: =SUM(F14:F14) -> 0 | M14: 8 | O14: 1 | R14: =N14*0 -> 0 | S14: =O14*1 -> 1 | T14: =P14*2 -> 0 | U14: =SUM(R14:R14) -> 0 | Y14: 8 | AA14: 1 | AD14: =Z14*0 -> 0 | AE14: =AA14*1 -> 1 | AF14: =AB14*2 -> 0 | AG14: =SUM(AD14:AD14) -> 0
A15: 9 | C15: 1 | F15: =B15*0 -> 0 | G15: =C15*1 -> 1 | H15: =D15*2 -> 0 | I15: =SUM(F15:F15) -> 0 | K15: รวมคะแนนพฤติกรรมอยู่ไม่นิ่ง/สมาธิสั้น 10 คะแนน | M15: 9 | O15: 1 | R15: =N15*0 -> 0 | S15: =O15*1 -> 1 | T15: =P15*2 -> 0 | U15: =SUM(R15:R15) -> 0 | W15: รวมคะแนนพฤติกรรมอยู่ไม่นิ่ง/สมาธิสั้น 10 คะแนน | Y15: 9 | AA15: 1 | AD15: =Z15*0 -> 0 | AE15: =AA15*1 -> 1 | AF15: =AB15*2 -> 0 | AG15: =SUM(AD15:AD15) -> 0 | AI15: รวมคะแนนพฤติกรรมอยู่ไม่นิ่ง/สมาธิสั้น 10 คะแนน
A16: 10 | B16: 1 | F16: =B16*0 -> 0 | G16: =C16*1 -> 0 | H16: =D16*2 -> 0 | I16: =SUM(F16:F16) -> 0 | K16: เกณฑ์ 0 - 5 ปกติ , 6 - 10 เสี่ยง/มีปัญหา | M16: 10 | N16: 1 | R16: =N16*0 -> 0 | S16: =O16*1 -> 0 | T16: =P16*2 -> 0 | U16: =SUM(R16:R16) -> 0 | W16: เกณฑ์ 0 - 5 ปกติ , 6 - 10 เสี่ยง/มีปัญหา | Y16: 10 | Z16: 1 | AD16: =Z16*0 -> 0 | AE16: =AA16*1 -> 0 | AF16: =AB16*2 -> 0 | AG16: =SUM(AD16:AD16) -> 0 | AI16: เกณฑ์ 0 - 5 ปกติ , 6 - 10 เสี่ยง/มีปัญหา
A17: 11 | D17: 1 | F17: =B17*0 -> 0 | G17: =C17*1 -> 0 | H17: =D17*2 -> 2 | I17: =SUM(F17:F17) -> 0 | J17: =I8+I16+I21+I27+I31 -> 0 | K17: =J17 -> 0 | M17: 11 | P17: 1 | R17: =N17*0 -> 0 | S17: =O17*1 -> 0 | T17: =P17*2 -> 2 | U17: =SUM(R17:R17) -> 0 | V17: =U8+U16+U21+U27+U31 -> 0 | W17: =V17 -> 0 | Y17: 11 | AB17: 1 | AD17: =Z17*0 -> 0 | AE17: =AA17*1 -> 0 | AF17: =AB17*2 -> 2 | AG17: =SUM(AD17:AD17) -> 0 | AH17: =AG8+AG16+AG21+AG27+AG31 -> 0 | AI17: =AH17 -> 0
A18: 12 | B18: 1 | F18: =B18*0 -> 0 | G18: =C18*1 -> 0 | H18: =D18*2 -> 0 | I18: =SUM(F18:F18) -> 0 | M18: 12 | N18: 1 | R18: =N18*0 -> 0 | S18: =O18*1 -> 0 | T18: =P18*2 -> 0 | U18: =SUM(R18:R18) -> 0 | Y18: 12 | Z18: 1 | AD18: =Z18*0 -> 0 | AE18: =AA18*1 -> 0 | AF18: =AB18*2 -> 0 | AG18: =SUM(AD18:AD18) -> 0
A19: 13 | B19: 1 | F19: =B19*0 -> 0 | G19: =C19*1 -> 0 | H19: =D19*2 -> 0 | I19: =SUM(F19:F19) -> 0 | M19: 13 | N19: 1 | R19: =N19*0 -> 0 | S19: =O19*1 -> 0 | T19: =P19*2 -> 0 | U19: =SUM(R19:R19) -> 0 | Y19: 13 | Z19: 1 | AD19: =Z19*0 -> 0 | AE19: =AA19*1 -> 0 | AF19: =AB19*2 -> 0 | AG19: =SUM(AD19:AD19) -> 0
A20: 14 | C20: 1 | F20: =B20*2 -> 0 | G20: =C20*1 -> 1 | H20: =D20*0 -> 0 | I20: =SUM(F20:F20) -> 0 | K20: รวมคะแนนด้านความสัมพันธ์กับเพื่อน 10 คะแนน | M20: 14 | O20: 1 | R20: =N20*2 -> 0 | S20: =O20*1 -> 1 | T20: =P20*0 -> 0 | U20: =SUM(R20:R20) -> 0 | W20: รวมคะแนนด้านความสัมพันธ์กับเพื่อน 10 คะแนน | Y20: 14 | AA20: 1 | AD20: =Z20*2 -> 0 | AE20: =AA20*1 -> 1 | AF20: =AB20*0 -> 0 | AG20: =SUM(AD20:AD20) -> 0 | AI20: รวมคะแนนด้านความสัมพันธ์กับเพื่อน 10 คะแนน
A21: 15 | C21: 1 | F21: =B21*2 -> 0 | G21: =C21*1 -> 1 | H21: =D21*0 -> 0 | I21: =SUM(F21:F21) -> 0 | K21: เกณฑ์ 0 - 3 ปกติ , 4 - 10 เสี่ยง/มีปัญหา | M21: 15 | O21: 1 | R21: =N21*2 -> 0 | S21: =O21*1 -> 1 | T21: =P21*0 -> 0 | U21: =SUM(R21:R21) -> 0 | W21: เกณฑ์ 0 - 3 ปกติ , 4 - 10 เสี่ยง/มีปัญหา | Y21: 15 | AA21: 1 | AD21: =Z21*2 -> 0 | AE21: =AA21*1 -> 1 | AF21: =AB21*0 -> 0 | AG21: =SUM(AD21:AD21) -> 0 | AI21: เกณฑ์ 0 - 3 ปกติ , 4 - 10 เสี่ยง/มีปัญหา
A22: 16 | B22: 1 | F22: =B22*0 -> 0 | G22: =C22*1 -> 0 | H22: =D22*2 -> 0 | I22: =SUM(F22:F22) -> 0 | J22: =I12+I17+I20+I25+I29 -> 0 | K22: =J22 -> 0 | M22: 16 | P22: 1 | R22: =N22*0 -> 0 | S22: =O22*1 -> 0 | T22: =P22*2 -> 2 | U22: =SUM(R22:R22) -> 0 | V22: =U12+U17+U20+U25+U29 -> 0 | W22: =V22 -> 0 | Y22: 16 | Z22: 1 | AD22: =Z22*0 -> 0 | AE22: =AA22*1 -> 0 | AF22: =AB22*2 -> 0 | AG22: =SUM(AD22:AD22) -> 0 | AH22: =AG12+AG17+AG20+AG25+AG29 -> 0 | AI22: =AH22 -> 0
A23: 17 | C23: 1 | F23: =B23*2 -> 0 | G23: =C23*1 -> 1 | H23: =D23*0 -> 0 | I23: =SUM(F23:F23) -> 0 | M23: 17 | O23: 1 | R23: =N23*2 -> 0 | S23: =O23*1 -> 1 | T23: =P23*0 -> 0 | U23: =SUM(R23:R23) -> 0 | Y23: 17 | AB23: 1 | AD23: =Z23*2 -> 0 | AE23: =AA23*1 -> 0 | AF23: =AB23*0 -> 0 | AG23: =SUM(AD23:AD23) -> 0
A24: 18 | B24: 1 | F24: =B24*2 -> 2 | G24: =C24*1 -> 0 | H24: =D24*0 -> 0 | I24: =SUM(F24:F24) -> 2 | M24: 18 | N24: 1 | R24: =N24*2 -> 2 | S24: =O24*1 -> 0 | T24: =P24*0 -> 0 | U24: =SUM(R24:R24) -> 2 | Y24: 18 | Z24: 1 | AD24: =Z24*2 -> 2 | AE24: =AA24*1 -> 0 | AF24: =AB24*0 -> 0 | AG24: =SUM(AD24:AD24) -> 2
A25: 19 | C25: 1 | F25: =B25*0 -> 0 | G25: =C25*1 -> 1 | H25: =D25*2 -> 0 | I25: =SUM(F25:F25) -> 0 | K25: รวมคะแนนสัมพันธภาพทางสังคม 30 คะแนน | M25: 19 | O25: 1 | R25: =N25*0 -> 0 | S25: =O25*1 -> 1 | T25: =P25*2 -> 0 | U25: =SUM(R25:R25) -> 0 | W25: รวมคะแนนสัมพันธภาพทางสังคม 30 คะแนน | Y25: 19 | Z25: 1 | AD25: =Z25*0 -> 0 | AE25: =AA25*1 -> 0 | AF25: =AB25*2 -> 0 | AG25: =SUM(AD25:AD25) -> 0 | AI25: รวมคะแนนสัมพันธภาพทางสังคม 30 คะแนน
A26: 20 | C26: 1 | F26: =B26*0 -> 0 | G26: =C26*1 -> 1 | H26: =D26*2 -> 0 | I26: =SUM(F26:F26) -> 0 | K26: เกณฑ์ 4 - 10 มีจุดแข็ง , 0 - 3 ไม่มีจุดแข็ง | M26: 20 | O26: 1 | R26: =N26*0 -> 0 | S26: =O26*1 -> 1 | T26: =P26*2 -> 0 | U26: =SUM(R26:R26) -> 0 | W26: เกณฑ์ 4 - 10 มีจุดแข็ง , 0 - 3 ไม่มีจุดแข็ง | Y26: 20 | AA26: 1 | AD26: =Z26*0 -> 0 | AE26: =AA26*1 -> 1 | AF26: =AB26*2 -> 0 | AG26: =SUM(AD26:AD26) -> 0 | AI26: เกณฑ์ 4 - 10 มีจุดแข็ง , 0 - 3 ไม่มีจุดแข็ง
A27: 21 | C27: 1 | F27: =B27*0 -> 0 | G27: =C27*1 -> 1 | H27: =D27*2 -> 0 | I27: =SUM(F27:F27) -> 0 | J27: =I7+I10+I15+I23+I26 -> 0 | K27: =J27 -> 0 | M27: 21 | O27: 1 | R27: =N27*0 -> 0 | S27: =O27*1 -> 1 | T27: =P27*2 -> 0 | U27: =SUM(R27:R27) -> 0 | V27: =U7+U10+U15+U23+U26 -> 0 | W27: =V27 -> 0 | Y27: 21 | AA27: 1 | AD27: =Z27*0 -> 0 | AE27: =AA27*1 -> 1 | AF27: =AB27*2 -> 0 | AG27: =SUM(AD27:AD27) -> 0 | AH27: =AG7+AG10+AG15+AG23+AG26 -> 0 | AI27: =AH27 -> 0
A28: 22 | B28: 1 | F28: =B28*0 -> 0 | G28: =C28*1 -> 0 | H28: =D28*2 -> 0 | I28: =SUM(F28:F28) -> 0 | M28: 22 | N28: 1 | R28: =N28*0 -> 0 | S28: =O28*1 -> 0 | T28: =P28*2 -> 0 | U28: =SUM(R28:R28) -> 0 | Y28: 22 | Z28: 1 | AD28: =Z28*0 -> 0 | AE28: =AA28*1 -> 0 | AF28: =AB28*2 -> 0 | AG28: =SUM(AD28:AD28) -> 0
A29: 23 | C29: 1 | F29: =B29*0 -> 0 | G29: =C29*1 -> 1 | H29: =D29*2 -> 0 | I29: =SUM(F29:F29) -> 0 | K29: คะแนนรวมพฤติกรรมที่เป็นปัญหา 4 ด้าน | M29: 23 | O29: 1 | R29: =N29*0 -> 0 | S29: =O29*1 -> 1 | T29: =P29*2 -> 0 | U29: =SUM(R29:R29) -> 0 | W29: คะแนนรวมพฤติกรรมที่เป็นปัญหา 4 ด้าน | Y29: 23 | AA29: 1 | AD29: =Z29*0 -> 0 | AE29: =AA29*1 -> 1 | AF29: =AB29*2 -> 0 | AG29: =SUM(AD29:AD29) -> 0 | AI29: คะแนนรวมพฤติกรรมที่เป็นปัญหา 4 ด้าน
A30: 24 | C30: 1 | F30: =B30*0 -> 0 | G30: =C30*1 -> 1 | H30: =D30*2 -> 0 | I30: =SUM(F30:F30) -> 0 | K30: เกณฑ์ 0 - 16 ปกติ , 17 - 40 เสี่ยง/มีปัญหา/มีปัญหา | M30: 24 | O30: 1 | R30: =N30*0 -> 0 | S30: =O30*1 -> 1 | T30: =P30*2 -> 0 | U30: =SUM(R30:R30) -> 0 | W30: เกณฑ์ 0 - 16 ปกติ , 17 - 40 เสี่ยง/มีปัญหา/มีปัญหา | Y30: 24 | AA30: 1 | AD30: =Z30*0 -> 0 | AE30: =AA30*1 -> 1 | AF30: =AB30*2 -> 0 | AG30: =SUM(AD30:AD30) -> 0 | AI30: เกณฑ์ 0 - 16 ปกติ , 17 - 40 เสี่ยง/มีปัญหา/มีปัญหา
A31: 25 | D31: 1 | F31: =B31*0 -> 0 | G31: =C31*1 -> 0 | H31: =D31*2 -> 2 | I31: =SUM(F31:F31) -> 0 | K31: =K7+K12+K17+K22 -> 4 | M31: 25 | P31: 1 | R31: =N31*0 -> 0 | S31: =O31*1 -> 0 | T31: =P31*2 -> 2 | U31: =SUM(R31:R31) -> 0 | W31: =W7+W12+W17+W22 -> 2 | Y31: 25 | AB31: 1 | AD31: =Z31*0 -> 0 | AE31: =AA31*1 -> 0 | AF31: =AB31*2 -> 2 | AG31: =SUM(AD31:AD31) -> 0 | AI31: =AI7+AI12+AI17+AI22 -> 4
A32: ด้านหลัง | B32: ปัญหาด้านอารมณ์ สมาธิ หรือความสามารถเข้ากับผู้อื่น | M32: ด้านหลัง | N32: ปัญหาด้านอารมณ์ สมาธิ หรือความสามารถเข้ากับผู้อื่น | Y32: ด้านหลัง | Z32: ปัญหาด้านอารมณ์ สมาธิ หรือความสามารถเข้ากับผู้อื่น
A33: ข้อ | B33: ไม่ | C33: เล็กน้อย | D33: ค่อนข้างมาก | E33: มาก | F33: ปัญหาเล็กน้อย | G33: ปัญหาชัดเจน | H33: ปัญหาอย่างมาก | I33: รวม | K33: สรุปการแปลผลด้านหลัง | M33: ข้อ | N33: ไม่ | O33: เล็กน้อย | P33: ค่อนข้างมาก | Q33: มาก | R33: ปัญหาเล็กน้อย | S33: ปัญหาชัดเจน | T33: ปัญหาอย่างมาก | U33: รวม | W33: สรุปการแปลผลด้านหลัง | Y33: ข้อ | Z33: ไม่ | AA33: เล็กน้อย | AB33: ค่อนข้างมาก | AC33: มาก | AD33: ปัญหาเล็กน้อย | AE33: ปัญหาชัดเจน | AF33: ปัญหาอย่างมาก | AG33: รวม | AI33: สรุปการแปลผลด้านหลัง
A34: อารมณ์ | F34: =C34*0 -> 0 | G34: =D34*1 -> 0 | H34: =E34*2 -> 0 | I34: =SUM(F34:F34) -> 0 | K34: เกณฑ์ 0 ปกติ | M34: อารมณ์ | R34: =O34*0 -> 0 | S34: =P34*1 -> 0 | T34: =Q34*2 -> 0 | U34: =SUM(R34:R34) -> 0 | W34: เกณฑ์ 0 ปกติ | Y34: อารมณ์ | AD34: =AA34*0 -> 0 | AE34: =AB34*1 -> 0 | AF34: =AC34*2 -> 0 | AG34: =SUM(AD34:AD34) -> 0 | AI34: เกณฑ์ 0 ปกติ
A35: เวลา | F35: =C35*0 -> 0 | G35: =D35*1 -> 0 | H35: =E35*2 -> 0 | I35: =SUM(F35:F35) -> 0 | J35: =I34+I35+I36+I37+I38+I39+I40+I41 -> 0 | K35: คะแนนรวม 1 คะแนนขึ้นไป เสี่ยง/มีปัญหา | M35: เวลา | R35: =O35*0 -> 0 | S35: =P35*1 -> 0 | T35: =Q35*2 -> 0 | U35: =SUM(R35:R35) -> 0 | V35: =U34+U35+U36+U37+U38+U39+U40+U41 -> 0 | W35: คะแนนรวม 1 คะแนนขึ้นไป เสี่ยง/มีปัญหา | Y35: เวลา | AD35: =AA35*0 -> 0 | AE35: =AB35*1 -> 0 | AF35: =AC35*2 -> 0 | AG35: =SUM(AD35:AD35) -> 0 | AH35: =AG34+AG35+AG36+AG37+AG38+AG39+AG40+AG41 -> 0 | AI35: คะแนนรวม 1 คะแนนขึ้นไป เสี่ยง/มีปัญหา
A36: รู้สึก | F36: =C36*0 -> 0 | G36: =D36*1 -> 0 | H36: =E36*2 -> 0 | I36: =SUM(F36:F36) -> 0 | M36: รู้สึก | R36: =O36*0 -> 0 | S36: =P36*1 -> 0 | T36: =Q36*2 -> 0 | U36: =SUM(R36:R36) -> 0 | Y36: รู้สึก | AD36: =AA36*0 -> 0 | AE36: =AB36*1 -> 0 | AF36: =AC36*2 -> 0 | AG36: =SUM(AD36:AD36) -> 0
A37: ความเป็นอยู่ | F37: =C37*0 -> 0 | G37: =D37*1 -> 0 | H37: =E37*2 -> 0 | I37: =SUM(F37:F37) -> 0 | K37: =J35 -> 0 | M37: ความเป็นอยู่ | R37: =O37*0 -> 0 | S37: =P37*1 -> 0 | T37: =Q37*2 -> 0 | U37: =SUM(R37:R37) -> 0 | W37: =V35 -> 0 | Y37: ความเป็นอยู่ | AD37: =AA37*0 -> 0 | AE37: =AB37*1 -> 0 | AF37: =AC37*2 -> 0 | AG37: =SUM(AD37:AD37) -> 0 | AI37: =AH35 -> 0
A38: การคบเพื่อน | F38: =C38*0 -> 0 | G38: =D38*1 -> 0 | H38: =E38*2 -> 0 | I38: =SUM(F38:F38) -> 0 | M38: การคบเพื่อน | R38: =O38*0 -> 0 | S38: =P38*1 -> 0 | T38: =Q38*2 -> 0 | U38: =SUM(R38:R38) -> 0 | Y38: การคบเพื่อน | AD38: =AA38*0 -> 0 | AE38: =AB38*1 -> 0 | AF38: =AC38*2 -> 0 | AG38: =SUM(AD38:AD38) -> 0
A39: การเรียนในห้องเรียน | F39: =C39*0 -> 0 | G39: =D39*1 -> 0 | H39: =E39*2 -> 0 | I39: =SUM(F39:F39) -> 0 | M39: การเรียนในห้องเรียน | R39: =O39*0 -> 0 | S39: =P39*1 -> 0 | T39: =Q39*2 -> 0 | U39: =SUM(R39:R39) -> 0 | Y39: การเรียนในห้องเรียน | AD39: =AA39*0 -> 0 | AE39: =AB39*1 -> 0 | AF39: =AC39*2 -> 0 | AG39: =SUM(AD39:AD39) -> 0
A40: กิจกรรมยามว่าง | F40: =C40*0 -> 0 | G40: =D40*1 -> 0 | H40: =E40*2 -> 0 | I40: =SUM(F40:F40) -> 0 | M40: กิจกรรมยามว่าง | R40: =O40*0 -> 0 | S40: =P40*1 -> 0 | T40: =Q40*2 -> 0 | U40: =SUM(R40:R40) -> 0 | Y40: กิจกรรมยามว่าง | AD40: =AA40*0 -> 0 | AE40: =AB40*1 -> 0 | AF40: =AC40*2 -> 0 | AG40: =SUM(AD40:AD40) -> 0
...

Sheet 02
A1: ผลการประเมินพฤติกรรมตนเอง (SDQ) | M1: ผลการประเมินพฤติกรรม ครูประเมินนักเรียน (SDQ) | Y1: ผลการประเมินพฤติกรรม ผู้ปกครองประเมินนักเรียน (SDQ)
A2: =ข้อมูล!C7 -> โรงเรียนเทศบาลท่าอิฐ อำเภอเมือง จังหวัดอุตรดิตถ์ | M2: =ข้อมูล!C7 -> โรงเรียนเทศบาลท่าอิฐ อำเภอเมือง จังหวัดอุตรดิตถ์ | Y2: โรงเรียนเทศบาลท่าอิฐ อำเภอเมือง จังหวัดอุตรดิตถ์
A3: ชื่อ-สกุล | B3: =รายชื่อ!B2 -> เด็กชาย | C3: =รายชื่อ!C2 -> นพธรรศ | D3: =รายชื่อ!D2 -> ปั่นจีด | K3: 2 | M3: ชื่อ-สกุล | N3: =รายชื่อ!B2 -> เด็กชาย | O3: =รายชื่อ!C2 -> นพธรรศ | P3: =รายชื่อ!D2 -> ปั่นจีด | W3: 2 | Y3: ชื่อ-สกุล | Z3: =รายชื่อ!B2 -> เด็กชาย | AA3: =รายชื่อ!C2 -> นพธรรศ | AB3: =รายชื่อ!D2 -> ปั่นจีด | AI3: 2
A4: SDQ1 | M4: SDQ2 | Y4: SDQ3
A5: รายการประเมินโดยนักเรียน | F5: คะแนน | K5: รวมคะแนนด้านอารมณ์ 10 คะแนน | M5: รายการประเมินโดยครู | R5: คะแนน | W5: รวมคะแนนด้านอารมณ์ 10 คะแนน | Y5: รายการประเมินโดยผู้ปกครอง | AD5: คะแนน | AI5: รวมคะแนนด้านอารมณ์ 10 คะแนน
A6: ข้อที่ | B6: ไม่จริง | C6: ค่อนข้างจริง | D6: จริง | F6: ไม่จริง | G6: ค่อนข้างจริง | H6: จริง | I6: รวม | K6: เกณฑ์ 0 - 5 ปกติ , 6 - 10 เสี่ยง/มีปัญหา | M6: ข้อที่ | N6: ไม่จริง | O6: ค่อนข้างจริง | P6: จริง | R6: ไม่จริง | S6: ค่อนข้างจริง | T6: จริง | U6: รวม | W6: เกณฑ์ 0 - 5 ปกติ , 6 - 10 เสี่ยง/มีปัญหา | Y6: ข้อที่ | Z6: ไม่จริง | AA6: ค่อนข้างจริง | AB6: จริง | AD6: ไม่จริง | AE6: ค่อนข้างจริง | AF6: จริง | AG6: รวม | AI6: เกณฑ์ 0 - 5 ปกติ , 6 - 10 เสี่ยง/มีปัญหา
A7: 1 | B7: 1 | F7: =B7*0 -> 0 | G7: =C7*1 -> 0 | H7: =D7*2 -> 0 | I7: =SUM(F7:F7) -> 0 | J7: =I9+I14+I19+I22+I30 -> 0 | K7: =J7 -> 0 | M7: 1 | O7: 1 | R7: =N7*0 -> 0 | S7: =O7*1 -> 1 | T7: =P7*2 -> 0 | U7: =SUM(R7:R7) -> 0 | V7: =U9+U14+U19+U22+U30 -> 0 | W7: =V7 -> 0 | Y7: 1 | AA7: 1 | AD7: =Z7*0 -> 0 | AE7: =AA7*1 -> 1 | AF7: =AB7*2 -> 0 | AG7: =SUM(AD7:AD7) -> 0 | AH7: =AG9+AG14+AG19+AG22+AG30 -> 0 | AI7: =AH7 -> 0
A8: 2 | D8: 1 | F8: =B8*0 -> 0 | G8: =C8*1 -> 0 | H8: =D8*2 -> 2 | I8: =SUM(F8:F8) -> 0 | M8: 2 | O8: 1 | R8: =N8*0 -> 0 | S8: =O8*1 -> 1 | T8: =P8*2 -> 0 | U8: =SUM(R8:R8) -> 0 | Y8: 2 | AB8: 1 | AD8: =Z8*0 -> 0 | AE8: =AA8*1 -> 0 | AF8: =AB8*2 -> 2 | AG8: =SUM(AD8:AD8) -> 0
A9: 3 | C9: 1 | F9: =B9*0 -> 0 | G9: =C9*1 -> 1 | H9: =D9*2 -> 0 | I9: =SUM(F9:F9) -> 0 | M9: 3 | O9: 1 | R9: =N9*0 -> 0 | S9: =O9*1 -> 1 | T9: =P9*2 -> 0 | U9: =SUM(R9:R9) -> 0 | Y9: 3 | AA9: 1 | AD9: =Z9*0 -> 0 | AE9: =AA9*1 -> 1 | AF9: =AB9*2 -> 0 | AG9: =SUM(AD9:AD9) -> 0
A10: 4 | B10: 1 | F10: =B10*0 -> 0 | G10: =C10*1 -> 0 | H10: =D10*2 -> 0 | I10: =SUM(F10:F10) -> 0 | K10: รวมคะแนนด้านความประพฤติ/เกเร 10 คะแนน | M10: 4 | O10: 1 | R10: =N10*0 -> 0 | S10: =O10*1 -> 1 | T10: =P10*2 -> 0 | U10: =SUM(R10:R10) -> 0 | W10: รวมคะแนนด้านความประพฤติ/เกเร 10 คะแนน | Y10: 4 | AA10: 1 | AD10: =Z10*0 -> 0 | AE10: =AA10*1 -> 1 | AF10: =AB10*2 -> 0 | AG10: =SUM(AD10:AD10) -> 0 | AI10: รวมคะแนนด้านความประพฤติ/เกเร 10 คะแนน
A11: 5 | D11: 1 | F11: =B11*0 -> 0 | G11: =C11*1 -> 0 | H11: =D11*2 -> 2 | I11: =SUM(F11:F11) -> 0 | K11: เกณฑ์ 0 - 4 ปกติ , 5 - 10 เสี่ยง/มีปัญหา | M11: 5 | O11: 1 | R11: =N11*0 -> 0 | S11: =O11*1 -> 1 | T11: =P11*2 -> 0 | U11: =SUM(R11:R11) -> 0 | W11: เกณฑ์ 0 - 4 ปกติ , 5 - 10 เสี่ยง/มีปัญหา | Y11: 5 | AA11: 1 | AD11: =Z11*0 -> 0 | AE11: =AA11*1 -> 1 | AF11: =AB11*2 -> 0 | AG11: =SUM(AD11:AD11) -> 0 | AI11: เกณฑ์ 0 - 4 ปกติ , 5 - 10 เสี่ยง/มีปัญหา
A12: 6 | B12: 1 | F12: =B12*0 -> 0 | G12: =C12*1 -> 0 | H12: =D12*2 -> 0 | I12: =SUM(F12:F12) -> 0 | J12: =I11+I13+I18+I24+I28 -> 2 | K12: =J12 -> 2 | M12: 6 | N12: 1 | R12: =N12*0 -> 0 | S12: =O12*1 -> 0 | T12: =P12*2 -> 0 | U12: =SUM(R12:R12) -> 0 | V12: =U11+U13+U18+U24+U28 -> 2 | W12: =V12 -> 2 | Y12: 6 | AA12: 1 | AD12: =Z12*0 -> 0 | AE12: =AA12*1 -> 1 | AF12: =AB12*2 -> 0 | AG12: =SUM(AD12:AD12) -> 0 | AH12: =AG11+AG13+AG18+AG24+AG28 -> 2 | AI12: =AH12 -> 2
A13: 7 | C13: 1 | F13: =B13*2 -> 0 | G13: =C13*1 -> 1 | H13: =D13*0 -> 0 | I13: =SUM(F13:F13) -> 0 | M13: 7 | O13: 1 | R13: =N13*2 -> 0 | S13: =O13*1 -> 1 | T13: =P13*0 -> 0 | U13: =SUM(R13:R13) -> 0 | Y13: 7 | AA13: 1 | AD13: =Z13*2 -> 0 | AE13: =AA13*1 -> 1 | AF13: =AB13*0 -> 0 | AG13: =SUM(AD13:AD13) -> 0
A14: 8 | D14: 1 | F14: =B14*0 -> 0 | G14: =C14*1 -> 0 | H14: =D14*2 -> 2 | I14: =SUM(F14:F14) -> 0 | M14: 8 | O14: 1 | R14: =N14*0 -> 0 | S14: =O14*1 -> 1 | T14: =P14*2 -> 0 | U14: =SUM(R14:R14) -> 0 | Y14: 8 | AB14: 1 | AD14: =Z14*0 -> 0 | AE14: =AA14*1 -> 0 | AF14: =AB14*2 -> 2 | AG14: =SUM(AD14:AD14) -> 0
A15: 9 | B15: 1 | F15: =B15*0 -> 0 | G15: =C15*1 -> 0 | H15: =D15*2 -> 0 | I15: =SUM(F15:F15) -> 0 | K15: รวมคะแนนพฤติกรรมอยู่ไม่นิ่ง/สมาธิสั้น 10 คะแนน | M15: 9 | O15: 1 | R15: =N15*0 -> 0 | S15: =O15*1 -> 1 | T15: =P15*2 -> 0 | U15: =SUM(R15:R15) -> 0 | W15: รวมคะแนนพฤติกรรมอยู่ไม่นิ่ง/สมาธิสั้น 10 คะแนน | Y15: 9 | AA15: 1 | AD15: =Z15*0 -> 0 | AE15: =AA15*1 -> 1 | AF15: =AB15*2 -> 0 | AG15: =SUM(AD15:AD15) -> 0 | AI15: รวมคะแนนพฤติกรรมอยู่ไม่นิ่ง/สมาธิสั้น 10 คะแนน
A16: 10 | C16: 1 | F16: =B16*0 -> 0 | G16: =C16*1 -> 1 | H16: =D16*2 -> 0 | I16: =SUM(F16:F16) -> 0 | K16: เกณฑ์ 0 - 5 ปกติ , 6 - 10 เสี่ยง/มีปัญหา | M16: 10 | O16: 1 | R16: =N16*0 -> 0 | S16: =O16*1 -> 1 | T16: =P16*2 -> 0 | U16: =SUM(R16:R16) -> 0 | W16: เกณฑ์ 0 - 5 ปกติ , 6 - 10 เสี่ยง/มีปัญหา | Y16: 10 | AA16: 1 | AD16: =Z16*0 -> 0 | AE16: =AA16*1 -> 1 | AF16: =AB16*2 -> 0 | AG16: =SUM(AD16:AD16) -> 0 | AI16: เกณฑ์ 0 - 5 ปกติ , 6 - 10 เสี่ยง/มีปัญหา
A17: 11 | D17: 1 | F17: =B17*0 -> 0 | G17: =C17*1 -> 0 | H17: =D17*2 -> 2 | I17: =SUM(F17:F17) -> 0 | J17: =I8+I16+I21+I27+I31 -> 0 | K17: =J17 -> 0 | M17: 11 | P17: 1 | R17: =N17*0 -> 0 | S17: =O17*1 -> 0 | T17: =P17*2 -> 2 | U17: =SUM(R17:R17) -> 0 | V17: =U8+U16+U21+U27+U31 -> 0 | W17: =V17 -> 0 | Y17: 11 | AB17: 1 | AD17: =Z17*0 -> 0 | AE17: =AA17*1 -> 0 | AF17: =AB17*2 -> 2 | AG17: =SUM(AD17:AD17) -> 0 | AH17: =AG8+AG16+AG21+AG27+AG31 -> 0 | AI17: =AH17 -> 0
A18: 12 | C18: 1 | F18: =B18*0 -> 0 | G18: =C18*1 -> 1 | H18: =D18*2 -> 0 | I18: =SUM(F18:F18) -> 0 | M18: 12 | N18: 1 | R18: =N18*0 -> 0 | S18: =O18*1 -> 0 | T18: =P18*2 -> 0 | U18: =SUM(R18:R18) -> 0 | Y18: 12 | Z18: 1 | AD18: =Z18*0 -> 0 | AE18: =AA18*1 -> 0 | AF18: =AB18*2 -> 0 | AG18: =SUM(AD18:AD18) -> 0
A19: 13 | B19: 1 | F19: =B19*0 -> 0 | G19: =C19*1 -> 0 | H19: =D19*2 -> 0 | I19: =SUM(F19:F19) -> 0 | M19: 13 | N19: 1 | R19: =N19*0 -> 0 | S19: =O19*1 -> 0 | T19: =P19*2 -> 0 | U19: =SUM(R19:R19) -> 0 | Y19: 13 | Z19: 1 | AD19: =Z19*0 -> 0 | AE19: =AA19*1 -> 0 | AF19: =AB19*2 -> 0 | AG19: =SUM(AD19:AD19) -> 0
A20: 14 | B20: 1 | F20: =B20*2 -> 2 | G20: =C20*1 -> 0 | H20: =D20*0 -> 0 | I20: =SUM(F20:F20) -> 2 | K20: รวมคะแนนด้านความสัมพันธ์กับเพื่อน 10 คะแนน | M20: 14 | O20: 1 | R20: =N20*2 -> 0 | S20: =O20*1 -> 1 | T20: =P20*0 -> 0 | U20: =SUM(R20:R20) -> 0 | W20: รวมคะแนนด้านความสัมพันธ์กับเพื่อน 10 คะแนน | Y20: 14 | AA20: 1 | AD20: =Z20*2 -> 0 | AE20: =AA20*1 -> 1 | AF20: =AB20*0 -> 0 | AG20: =SUM(AD20:AD20) -> 0 | AI20: รวมคะแนนด้านความสัมพันธ์กับเพื่อน 10 คะแนน
A21: 15 | D21: 1 | F21: =B21*2 -> 0 | G21: =C21*1 -> 0 | H21: =D21*0 -> 0 | I21: =SUM(F21:F21) -> 0 | K21: เกณฑ์ 0 - 3 ปกติ , 4 - 10 เสี่ยง/มีปัญหา | M21: 15 | O21: 1 | R21: =N21*2 -> 0 | S21: =O21*1 -> 1 | T21: =P21*0 -> 0 | U21: =SUM(R21:R21) -> 0 | W21: เกณฑ์ 0 - 3 ปกติ , 4 - 10 เสี่ยง/มีปัญหา | Y21: 15 | AB21: 1 | AD21: =Z21*2 -> 0 | AE21: =AA21*1 -> 0 | AF21: =AB21*0 -> 0 | AG21: =SUM(AD21:AD21) -> 0 | AI21: เกณฑ์ 0 - 3 ปกติ , 4 - 10 เสี่ยง/มีปัญหา
A22: 16 | B22: 1 | F22: =B22*0 -> 0 | G22: =C22*1 -> 0 | H22: =D22*2 -> 0 | I22: =SUM(F22:F22) -> 0 | J22: =I12+I17+I20+I25+I29 -> 2 | K22: =J22 -> 2 | M22: 16 | O22: 1 | R22: =N22*0 -> 0 | S22: =O22*1 -> 1 | T22: =P22*2 -> 0 | U22: =SUM(R22:R22) -> 0 | V22: =U12+U17+U20+U25+U29 -> 0 | W22: =V22 -> 0 | Y22: 16 | Z22: 1 | AD22: =Z22*0 -> 0 | AE22: =AA22*1 -> 0 | AF22: =AB22*2 -> 0 | AG22: =SUM(AD22:AD22) -> 0 | AH22: =AG12+AG17+AG20+AG25+AG29 -> 0 | AI22: =AH22 -> 0
A23: 17 | B23: 1 | F23: =B23*2 -> 2 | G23: =C23*1 -> 0 | H23: =D23*0 -> 0 | I23: =SUM(F23:F23) -> 2 | M23: 17 | O23: 1 | R23: =N23*2 -> 0 | S23: =O23*1 -> 1 | T23: =P23*0 -> 0 | U23: =SUM(R23:R23) -> 0 | Y23: 17 | Z23: 1 | AD23: =Z23*2 -> 2 | AE23: =AA23*1 -> 0 | AF23: =AB23*0 -> 0 | AG23: =SUM(AD23:AD23) -> 2
A24: 18 | B24: 1 | F24: =B24*2 -> 2 | G24: =C24*1 -> 0 | H24: =D24*0 -> 0 | I24: =SUM(F24:F24) -> 2 | M24: 18 | N24: 1 | R24: =N24*2 -> 2 | S24: =O24*1 -> 0 | T24: =P24*0 -> 0 | U24: =SUM(R24:R24) -> 2 | Y24: 18 | Z24: 1 | AD24: =Z24*2 -> 2 | AE24: =AA24*1 -> 0 | AF24: =AB24*0 -> 0 | AG24: =SUM(AD24:AD24) -> 2
A25: 19 | B25: 1 | F25: =B25*0 -> 0 | G25: =C25*1 -> 0 | H25: =D25*2 -> 0 | I25: =SUM(F25:F25) -> 0 | K25: รวมคะแนนสัมพันธภาพทางสังคม 30 คะแนน | M25: 19 | N25: 1 | R25: =N25*0 -> 0 | S25: =O25*1 -> 0 | T25: =P25*2 -> 0 | U25: =SUM(R25:R25) -> 0 | W25: รวมคะแนนสัมพันธภาพทางสังคม 30 คะแนน | Y25: 19 | Z25: 1 | AD25: =Z25*0 -> 0 | AE25: =AA25*1 -> 0 | AF25: =AB25*2 -> 0 | AG25: =SUM(AD25:AD25) -> 0 | AI25: รวมคะแนนสัมพันธภาพทางสังคม 30 คะแนน
A26: 20 | C26: 1 | F26: =B26*0 -> 0 | G26: =C26*1 -> 1 | H26: =D26*2 -> 0 | I26: =SUM(F26:F26) -> 0 | K26: เกณฑ์ 4 - 10 มีจุดแข็ง , 0 - 3 ไม่มีจุดแข็ง | M26: 20 | P26: 1 | R26: =N26*0 -> 0 | S26: =O26*1 -> 0 | T26: =P26*2 -> 2 | U26: =SUM(R26:R26) -> 0 | W26: เกณฑ์ 4 - 10 มีจุดแข็ง , 0 - 3 ไม่มีจุดแข็ง | Y26: 20 | AA26: 1 | AD26: =Z26*0 -> 0 | AE26: =AA26*1 -> 1 | AF26: =AB26*2 -> 0 | AG26: =SUM(AD26:AD26) -> 0 | AI26: เกณฑ์ 4 - 10 มีจุดแข็ง , 0 - 3 ไม่มีจุดแข็ง
A27: 21 | B27: 1 | F27: =B27*0 -> 0 | G27: =C27*1 -> 0 | H27: =D27*2 -> 0 | I27: =SUM(F27:F27) -> 0 | J27: =I7+I10+I15+I23+I26 -> 2 | K27: =J27 -> 2 | M27: 21 | O27: 1 | R27: =N27*0 -> 0 | S27: =O27*1 -> 1 | T27: =P27*2 -> 0 | U27: =SUM(R27:R27) -> 0 | V27: =U7+U10+U15+U23+U26 -> 0 | W27: =V27 -> 0 | Y27: 21 | AA27: 1 | AD27: =Z27*0 -> 0 | AE27: =AA27*1 -> 1 | AF27: =AB27*2 -> 0 | AG27: =SUM(AD27:AD27) -> 0 | AH27: =AG7+AG10+AG15+AG23+AG26 -> 2 | AI27: =AH27 -> 2
A28: 22 | B28: 1 | F28: =B28*0 -> 0 | G28: =C28*1 -> 0 | H28: =D28*2 -> 0 | I28: =SUM(F28:F28) -> 0 | M28: 22 | N28: 1 | R28: =N28*0 -> 0 | S28: =O28*1 -> 0 | T28: =P28*2 -> 0 | U28: =SUM(R28:R28) -> 0 | Y28: 22 | Z28: 1 | AD28: =Z28*0 -> 0 | AE28: =AA28*1 -> 0 | AF28: =AB28*2 -> 0 | AG28: =SUM(AD28:AD28) -> 0
A29: 23 | B29: 1 | F29: =B29*0 -> 0 | G29: =C29*1 -> 0 | H29: =D29*2 -> 0 | I29: =SUM(F29:F29) -> 0 | K29: คะแนนรวมพฤติกรรมที่เป็นปัญหา 4 ด้าน | M29: 23 | O29: 1 | R29: =N29*0 -> 0 | S29: =O29*1 -> 1 | T29: =P29*2 -> 0 | U29: =SUM(R29:R29) -> 0 | W29: คะแนนรวมพฤติกรรมที่เป็นปัญหา 4 ด้าน | Y29: 23 | AA29: 1 | AD29: =Z29*0 -> 0 | AE29: =AA29*1 -> 1 | AF29: =AB29*2 -> 0 | AG29: =SUM(AD29:AD29) -> 0 | AI29: คะแนนรวมพฤติกรรมที่เป็นปัญหา 4 ด้าน
A30: 24 | B30: 1 | F30: =B30*0 -> 0 | G30: =C30*1 -> 0 | H30: =D30*2 -> 0 | I30: =SUM(F30:F30) -> 0 | K30: เกณฑ์ 0 - 16 ปกติ , 17 - 40 เสี่ยง/มีปัญหา/มีปัญหา | M30: 24 | O30: 1 | R30: =N30*0 -> 0 | S30: =O30*1 -> 1 | T30: =P30*2 -> 0 | U30: =SUM(R30:R30) -> 0 | W30: เกณฑ์ 0 - 16 ปกติ , 17 - 40 เสี่ยง/มีปัญหา/มีปัญหา | Y30: 24 | Z30: 1 | AD30: =Z30*0 -> 0 | AE30: =AA30*1 -> 0 | AF30: =AB30*2 -> 0 | AG30: =SUM(AD30:AD30) -> 0 | AI30: เกณฑ์ 0 - 16 ปกติ , 17 - 40 เสี่ยง/มีปัญหา/มีปัญหา
A31: 25 | C31: 1 | F31: =B31*0 -> 0 | G31: =C31*1 -> 1 | H31: =D31*2 -> 0 | I31: =SUM(F31:F31) -> 0 | K31: =K7+K12+K17+K22 -> 4 | M31: 25 | O31: 1 | R31: =N31*0 -> 0 | S31: =O31*1 -> 1 | T31: =P31*2 -> 0 | U31: =SUM(R31:R31) -> 0 | W31: =W7+W12+W17+W22 -> 2 | Y31: 25 | AA31: 1 | AD31: =Z31*0 -> 0 | AE31: =AA31*1 -> 1 | AF31: =AB31*2 -> 0 | AG31: =SUM(AD31:AD31) -> 0 | AI31: =AI7+AI12+AI17+AI22 -> 2
A32: ด้านหลัง | B32: ปัญหาด้านอารมณ์ สมาธิ หรือความสามารถเข้ากับผู้อื่น | M32: ด้านหลัง | N32: ปัญหาด้านอารมณ์ สมาธิ หรือความสามารถเข้ากับผู้อื่น | Y32: ด้านหลัง | Z32: ปัญหาด้านอารมณ์ สมาธิ หรือความสามารถเข้ากับผู้อื่น
A33: ข้อ | B33: ไม่ | C33: เล็กน้อย | D33: ค่อนข้างมาก | E33: มาก | F33: ปัญหาเล็กน้อย | G33: ปัญหาชัดเจน | H33: ปัญหาอย่างมาก | I33: รวม | K33: สรุปการแปลผลด้านหลัง | M33: ข้อ | N33: ไม่ | O33: เล็กน้อย | P33: ค่อนข้างมาก | Q33: มาก | R33: ปัญหาเล็กน้อย | S33: ปัญหาชัดเจน | T33: ปัญหาอย่างมาก | U33: รวม | W33: สรุปการแปลผลด้านหลัง | Y33: ข้อ | Z33: ไม่ | AA33: เล็กน้อย | AB33: ค่อนข้างมาก | AC33: มาก | AD33: ปัญหาเล็กน้อย | AE33: ปัญหาชัดเจน | AF33: ปัญหาอย่างมาก | AG33: รวม | AI33: สรุปการแปลผลด้านหลัง
A34: อารมณ์ | F34: =C34*0 -> 0 | G34: =D34*1 -> 0 | H34: =E34*2 -> 0 | I34: =SUM(F34:F34) -> 0 | K34: เกณฑ์ 0 ปกติ | M34: อารมณ์ | R34: =O34*0 -> 0 | S34: =P34*1 -> 0 | T34: =Q34*2 -> 0 | U34: =SUM(R34:R34) -> 0 | W34: เกณฑ์ 0 ปกติ | Y34: อารมณ์ | AD34: =AA34*0 -> 0 | AE34: =AB34*1 -> 0 | AF34: =AC34*2 -> 0 | AG34: =SUM(AD34:AD34) -> 0 | AI34: เกณฑ์ 0 ปกติ
A35: เวลา | F35: =C35*0 -> 0 | G35: =D35*1 -> 0 | H35: =E35*2 -> 0 | I35: =SUM(F35:F35) -> 0 | J35: =I34+I35+I36+I37+I38+I39+I40+I41 -> 0 | K35: คะแนนรวม 1 คะแนนขึ้นไป เสี่ยง/มีปัญหา | M35: เวลา | R35: =O35*0 -> 0 | S35: =P35*1 -> 0 | T35: =Q35*2 -> 0 | U35: =SUM(R35:R35) -> 0 | V35: =U34+U35+U36+U37+U38+U39+U40+U41 -> 0 | W35: คะแนนรวม 1 คะแนนขึ้นไป เสี่ยง/มีปัญหา | Y35: เวลา | AD35: =AA35*0 -> 0 | AE35: =AB35*1 -> 0 | AF35: =AC35*2 -> 0 | AG35: =SUM(AD35:AD35) -> 0 | AH35: =AG34+AG35+AG36+AG37+AG38+AG39+AG40+AG41 -> 0 | AI35: คะแนนรวม 1 คะแนนขึ้นไป เสี่ยง/มีปัญหา
A36: รู้สึก | F36: =C36*0 -> 0 | G36: =D36*1 -> 0 | H36: =E36*2 -> 0 | I36: =SUM(F36:F36) -> 0 | M36: รู้สึก | R36: =O36*0 -> 0 | S36: =P36*1 -> 0 | T36: =Q36*2 -> 0 | U36: =SUM(R36:R36) -> 0 | Y36: รู้สึก | AD36: =AA36*0 -> 0 | AE36: =AB36*1 -> 0 | AF36: =AC36*2 -> 0 | AG36: =SUM(AD36:AD36) -> 0
A37: ความเป็นอยู่ | F37: =C37*0 -> 0 | G37: =D37*1 -> 0 | H37: =E37*2 -> 0 | I37: =SUM(F37:F37) -> 0 | K37: =J35 -> 0 | M37: ความเป็นอยู่ | R37: =O37*0 -> 0 | S37: =P37*1 -> 0 | T37: =Q37*2 -> 0 | U37: =SUM(R37:R37) -> 0 | W37: =V35 -> 0 | Y37: ความเป็นอยู่ | AD37: =AA37*0 -> 0 | AE37: =AB37*1 -> 0 | AF37: =AC37*2 -> 0 | AG37: =SUM(AD37:AD37) -> 0 | AI37: =AH35 -> 0
A38: การคบเพื่อน | F38: =C38*0 -> 0 | G38: =D38*1 -> 0 | H38: =E38*2 -> 0 | I38: =SUM(F38:F38) -> 0 | M38: การคบเพื่อน | R38: =O38*0 -> 0 | S38: =P38*1 -> 0 | T38: =Q38*2 -> 0 | U38: =SUM(R38:R38) -> 0 | Y38: การคบเพื่อน | AD38: =AA38*0 -> 0 | AE38: =AB38*1 -> 0 | AF38: =AC38*2 -> 0 | AG38: =SUM(AD38:AD38) -> 0
A39: การเรียนในห้องเรียน | F39: =C39*0 -> 0 | G39: =D39*1 -> 0 | H39: =E39*2 -> 0 | I39: =SUM(F39:F39) -> 0 | M39: การเรียนในห้องเรียน | R39: =O39*0 -> 0 | S39: =P39*1 -> 0 | T39: =Q39*2 -> 0 | U39: =SUM(R39:R39) -> 0 | Y39: การเรียนในห้องเรียน | AD39: =AA39*0 -> 0 | AE39: =AB39*1 -> 0 | AF39: =AC39*2 -> 0 | AG39: =SUM(AD39:AD39) -> 0
A40: กิจกรรมยามว่าง | F40: =C40*0 -> 0 | G40: =D40*1 -> 0 | H40: =E40*2 -> 0 | I40: =SUM(F40:F40) -> 0 | M40: กิจกรรมยามว่าง | R40: =O40*0 -> 0 | S40: =P40*1 -> 0 | T40: =Q40*2 -> 0 | U40: =SUM(R40:R40) -> 0 | Y40: กิจกรรมยามว่าง | AD40: =AA40*0 -> 0 | AE40: =AB40*1 -> 0 | AF40: =AC40*2 -> 0 | AG40: =SUM(AD40:AD40) -> 0
...

Sheet 03
A1: ผลการประเมินพฤติกรรมตนเอง (SDQ) | M1: ผลการประเมินพฤติกรรม ครูประเมินนักเรียน (SDQ) | Y1: ผลการประเมินพฤติกรรม ผู้ปกครองประเมินนักเรียน (SDQ)
A2: =ข้อมูล!C7 -> โรงเรียนเทศบาลท่าอิฐ อำเภอเมือง จังหวัดอุตรดิตถ์ | M2: =ข้อมูล!C7 -> โรงเรียนเทศบาลท่าอิฐ อำเภอเมือง จังหวัดอุตรดิตถ์ | Y2: โรงเรียนเทศบาลท่าอิฐ อำเภอเมือง จังหวัดอุตรดิตถ์
A3: ชื่อ-สกุล | B3: =รายชื่อ!B3 -> เด็กชาย | C3: =รายชื่อ!C3 -> นภัทร | D3: =รายชื่อ!D3 -> เอมเทศ | K3: 3 | M3: ชื่อ-สกุล | N3: =รายชื่อ!B3 -> เด็กชาย | O3: =รายชื่อ!C3 -> นภัทร | P3: =รายชื่อ!D3 -> เอมเทศ | W3: 3 | Y3: ชื่อ-สกุล | Z3: =รายชื่อ!B3 -> เด็กชาย | AA3: =รายชื่อ!C3 -> นภัทร | AB3: =รายชื่อ!D3 -> เอมเทศ | AI3: 3
A4: SDQ1 | M4: SDQ2 | Y4: SDQ3
A5: รายการประเมินโดยนักเรียน | F5: คะแนน | K5: รวมคะแนนด้านอารมณ์ 10 คะแนน | M5: รายการประเมินโดยครู | R5: คะแนน | W5: รวมคะแนนด้านอารมณ์ 10 คะแนน | Y5: รายการประเมินโดยผู้ปกครอง | AD5: คะแนน | AI5: รวมคะแนนด้านอารมณ์ 10 คะแนน
A6: ข้อที่ | B6: ไม่จริง | C6: ค่อนข้างจริง | D6: จริง | F6: ไม่จริง | G6: ค่อนข้างจริง | H6: จริง | I6: รวม | K6: เกณฑ์ 0 - 5 ปกติ , 6 - 10 เสี่ยง/มีปัญหา | M6: ข้อที่ | N6: ไม่จริง | O6: ค่อนข้างจริง | P6: จริง | R6: ไม่จริง | S6: ค่อนข้างจริง | T6: จริง | U6: รวม | W6: เกณฑ์ 0 - 5 ปกติ , 6 - 10 เสี่ยง/มีปัญหา | Y6: ข้อที่ | Z6: ไม่จริง | AA6: ค่อนข้างจริง | AB6: จริง | AD6: ไม่จริง | AE6: ค่อนข้างจริง | AF6: จริง | AG6: รวม | AI6: เกณฑ์ 0 - 5 ปกติ , 6 - 10 เสี่ยง/มีปัญหา
A7: 1 | D7: 1 | F7: =B7*0 -> 0 | G7: =C7*1 -> 0 | H7: =D7*2 -> 2 | I7: =SUM(F7:F7) -> 0 | J7: =I9+I14+I19+I22+I30 -> 0 | K7: =J7 -> 0 | M7: 1 | P7: 1 | R7: =N7*0 -> 0 | S7: =O7*1 -> 0 | T7: =P7*2 -> 2 | U7: =SUM(R7:R7) -> 0 | V7: =U9+U14+U19+U22+U30 -> 0 | W7: =V7 -> 0 | Y7: 1 | AB7: 1 | AD7: =Z7*0 -> 0 | AE7: =AA7*1 -> 0 | AF7: =AB7*2 -> 2 | AG7: =SUM(AD7:AD7) -> 0 | AH7: =AG9+AG14+AG19+AG22+AG30 -> 0 | AI7: =AH7 -> 0
A8: 2 | B8: 1 | F8: =B8*0 -> 0 | G8: =C8*1 -> 0 | H8: =D8*2 -> 0 | I8: =SUM(F8:F8) -> 0 | M8: 2 | N8: 1 | R8: =N8*0 -> 0 | S8: =O8*1 -> 0 | T8: =P8*2 -> 0 | U8: =SUM(R8:R8) -> 0 | Y8: 2 | AA8: 1 | AD8: =Z8*0 -> 0 | AE8: =AA8*1 -> 1 | AF8: =AB8*2 -> 0 | AG8: =SUM(AD8:AD8) -> 0
A9: 3 | B9: 1 | F9: =B9*0 -> 0 | G9: =C9*1 -> 0 | H9: =D9*2 -> 0 | I9: =SUM(F9:F9) -> 0 | M9: 3 | O9: 1 | R9: =N9*0 -> 0 | S9: =O9*1 -> 1 | T9: =P9*2 -> 0 | U9: =SUM(R9:R9) -> 0 | Y9: 3 | AA9: 1 | AD9: =Z9*0 -> 0 | AE9: =AA9*1 -> 1 | AF9: =AB9*2 -> 0 | AG9: =SUM(AD9:AD9) -> 0
A10: 4 | D10: 1 | F10: =B10*0 -> 0 | G10: =C10*1 -> 0 | H10: =D10*2 -> 2 | I10: =SUM(F10:F10) -> 0 | K10: รวมคะแนนด้านความประพฤติ/เกเร 10 คะแนน | M10: 4 | O10: 1 | R10: =N10*0 -> 0 | S10: =O10*1 -> 1 | T10: =P10*2 -> 0 | U10: =SUM(R10:R10) -> 0 | W10: รวมคะแนนด้านความประพฤติ/เกเร 10 คะแนน | Y10: 4 | AB10: 1 | AD10: =Z10*0 -> 0 | AE10: =AA10*1 -> 0 | AF10: =AB10*2 -> 2 | AG10: =SUM(AD10:AD10) -> 0 | AI10: รวมคะแนนด้านความประพฤติ/เกเร 10 คะแนน
A11: 5 | B11: 1 | F11: =B11*0 -> 0 | G11: =C11*1 -> 0 | H11: =D11*2 -> 0 | I11: =SUM(F11:F11) -> 0 | K11: เกณฑ์ 0 - 4 ปกติ , 5 - 10 เสี่ยง/มีปัญหา | M11: 5 | N11: 1 | R11: =N11*0 -> 0 | S11: =O11*1 -> 0 | T11: =P11*2 -> 0 | U11: =SUM(R11:R11) -> 0 | W11: เกณฑ์ 0 - 4 ปกติ , 5 - 10 เสี่ยง/มีปัญหา | Y11: 5 | AA11: 1 | AD11: =Z11*0 -> 0 | AE11: =AA11*1 -> 1 | AF11: =AB11*2 -> 0 | AG11: =SUM(AD11:AD11) -> 0 | AI11: เกณฑ์ 0 - 4 ปกติ , 5 - 10 เสี่ยง/มีปัญหา
A12: 6 | C12: 1 | F12: =B12*0 -> 0 | G12: =C12*1 -> 1 | H12: =D12*2 -> 0 | I12: =SUM(F12:F12) -> 0 | J12: =I11+I13+I18+I24+I28 -> 2 | K12: =J12 -> 2 | M12: 6 | O12: 1 | R12: =N12*0 -> 0 | S12: =O12*1 -> 1 | T12: =P12*2 -> 0 | U12: =SUM(R12:R12) -> 0 | V12: =U11+U13+U18+U24+U28 -> 2 | W12: =V12 -> 2 | Y12: 6 | AA12: 1 | AD12: =Z12*0 -> 0 | AE12: =AA12*1 -> 1 | AF12: =AB12*2 -> 0 | AG12: =SUM(AD12:AD12) -> 0 | AH12: =AG11+AG13+AG18+AG24+AG28 -> 0 | AI12: =AH12 -> 0
A13: 7 | D13: 1 | F13: =B13*2 -> 0 | G13: =C13*1 -> 0 | H13: =D13*0 -> 0 | I13: =SUM(F13:F13) -> 0 | M13: 7 | O13: 1 | R13: =N13*2 -> 0 | S13: =O13*1 -> 1 | T13: =P13*0 -> 0 | U13: =SUM(R13:R13) -> 0 | Y13: 7 | AA13: 1 | AD13: =Z13*2 -> 0 | AE13: =AA13*1 -> 1 | AF13: =AB13*0 -> 0 | AG13: =SUM(AD13:AD13) -> 0
A14: 8 | B14: 1 | F14: =B14*0 -> 0 | G14: =C14*1 -> 0 | H14: =D14*2 -> 0 | I14: =SUM(F14:F14) -> 0 | M14: 8 | O14: 1 | R14: =N14*0 -> 0 | S14: =O14*1 -> 1 | T14: =P14*2 -> 0 | U14: =SUM(R14:R14) -> 0 | Y14: 8 | Z14: 1 | AD14: =Z14*0 -> 0 | AE14: =AA14*1 -> 0 | AF14: =AB14*2 -> 0 | AG14: =SUM(AD14:AD14) -> 0
A15: 9 | D15: 1 | F15: =B15*0 -> 0 | G15: =C15*1 -> 0 | H15: =D15*2 -> 2 | I15: =SUM(F15:F15) -> 0 | K15: รวมคะแนนพฤติกรรมอยู่ไม่นิ่ง/สมาธิสั้น 10 คะแนน | M15: 9 | P15: 1 | R15: =N15*0 -> 0 | S15: =O15*1 -> 0 | T15: =P15*2 -> 2 | U15: =SUM(R15:R15) -> 0 | W15: รวมคะแนนพฤติกรรมอยู่ไม่นิ่ง/สมาธิสั้น 10 คะแนน | Y15: 9 | AB15: 1 | AD15: =Z15*0 -> 0 | AE15: =AA15*1 -> 0 | AF15: =AB15*2 -> 2 | AG15: =SUM(AD15:AD15) -> 0 | AI15: รวมคะแนนพฤติกรรมอยู่ไม่นิ่ง/สมาธิสั้น 10 คะแนน
A16: 10 | B16: 1 | F16: =B16*0 -> 0 | G16: =C16*1 -> 0 | H16: =D16*2 -> 0 | I16: =SUM(F16:F16) -> 0 | K16: เกณฑ์ 0 - 5 ปกติ , 6 - 10 เสี่ยง/มีปัญหา | M16: 10 | N16: 1 | R16: =N16*0 -> 0 | S16: =O16*1 -> 0 | T16: =P16*2 -> 0 | U16: =SUM(R16:R16) -> 0 | W16: เกณฑ์ 0 - 5 ปกติ , 6 - 10 เสี่ยง/มีปัญหา | Y16: 10 | Z16: 1 | AD16: =Z16*0 -> 0 | AE16: =AA16*1 -> 0 | AF16: =AB16*2 -> 0 | AG16: =SUM(AD16:AD16) -> 0 | AI16: เกณฑ์ 0 - 5 ปกติ , 6 - 10 เสี่ยง/มีปัญหา
A17: 11 | D17: 1 | F17: =B17*0 -> 0 | G17: =C17*1 -> 0 | H17: =D17*2 -> 2 | I17: =SUM(F17:F17) -> 0 | J17: =I8+I16+I21+I27+I31 -> 2 | K17: =J17 -> 2 | M17: 11 | P17: 1 | R17: =N17*0 -> 0 | S17: =O17*1 -> 0 | T17: =P17*2 -> 2 | U17: =SUM(R17:R17) -> 0 | V17: =U8+U16+U21+U27+U31 -> 0 | W17: =V17 -> 0 | Y17: 11 | AB17: 1 | AD17: =Z17*0 -> 0 | AE17: =AA17*1 -> 0 | AF17: =AB17*2 -> 2 | AG17: =SUM(AD17:AD17) -> 0 | AH17: =AG8+AG16+AG21+AG27+AG31 -> 0 | AI17: =AH17 -> 0
A18: 12 | B18: 1 | F18: =B18*0 -> 0 | G18: =C18*1 -> 0 | H18: =D18*2 -> 0 | I18: =SUM(F18:F18) -> 0 | M18: 12 | N18: 1 | R18: =N18*0 -> 0 | S18: =O18*1 -> 0 | T18: =P18*2 -> 0 | U18: =SUM(R18:R18) -> 0 | Y18: 12 | Z18: 1 | AD18: =Z18*0 -> 0 | AE18: =AA18*1 -> 0 | AF18: =AB18*2 -> 0 | AG18: =SUM(AD18:AD18) -> 0
A19: 13 | B19: 1 | F19: =B19*0 -> 0 | G19: =C19*1 -> 0 | H19: =D19*2 -> 0 | I19: =SUM(F19:F19) -> 0 | M19: 13 | O19: 1 | R19: =N19*0 -> 0 | S19: =O19*1 -> 1 | T19: =P19*2 -> 0 | U19: =SUM(R19:R19) -> 0 | Y19: 13 | Z19: 1 | AD19: =Z19*0 -> 0 | AE19: =AA19*1 -> 0 | AF19: =AB19*2 -> 0 | AG19: =SUM(AD19:AD19) -> 0
A20: 14 | C20: 1 | F20: =B20*2 -> 0 | G20: =C20*1 -> 1 | H20: =D20*0 -> 0 | I20: =SUM(F20:F20) -> 0 | K20: รวมคะแนนด้านความสัมพันธ์กับเพื่อน 10 คะแนน | M20: 14 | N20: 1 | R20: =N20*2 -> 2 | S20: =O20*1 -> 0 | T20: =P20*0 -> 0 | U20: =SUM(R20:R20) -> 2 | W20: รวมคะแนนด้านความสัมพันธ์กับเพื่อน 10 คะแนน | Y20: 14 | AA20: 1 | AD20: =Z20*2 -> 0 | AE20: =AA20*1 -> 1 | AF20: =AB20*0 -> 0 | AG20: =SUM(AD20:AD20) -> 0 | AI20: รวมคะแนนด้านความสัมพันธ์กับเพื่อน 10 คะแนน
A21: 15 | B21: 1 | F21: =B21*2 -> 2 | G21: =C21*1 -> 0 | H21: =D21*0 -> 0 | I21: =SUM(F21:F21) -> 2 | K21: เกณฑ์ 0 - 3 ปกติ , 4 - 10 เสี่ยง/มีปัญหา | M21: 15 | O21: 1 | R21: =N21*2 -> 0 | S21: =O21*1 -> 1 | T21: =P21*0 -> 0 | U21: =SUM(R21:R21) -> 0 | W21: เกณฑ์ 0 - 3 ปกติ , 4 - 10 เสี่ยง/มีปัญหา | Y21: 15 | AA21: 1 | AD21: =Z21*2 -> 0 | AE21: =AA21*1 -> 1 | AF21: =AB21*0 -> 0 | AG21: =SUM(AD21:AD21) -> 0 | AI21: เกณฑ์ 0 - 3 ปกติ , 4 - 10 เสี่ยง/มีปัญหา
A22: 16 | C22: 1 | F22: =B22*0 -> 0 | G22: =C22*1 -> 1 | H22: =D22*2 -> 0 | I22: =SUM(F22:F22) -> 0 | J22: =I12+I17+I20+I25+I29 -> 0 | K22: =J22 -> 0 | M22: 16 | O22: 1 | R22: =N22*0 -> 0 | S22: =O22*1 -> 1 | T22: =P22*2 -> 0 | U22: =SUM(R22:R22) -> 0 | V22: =U12+U17+U20+U25+U29 -> 2 | W22: =V22 -> 2 | Y22: 16 | AB22: 1 | AD22: =Z22*0 -> 0 | AE22: =AA22*1 -> 0 | AF22: =AB22*2 -> 2 | AG22: =SUM(AD22:AD22) -> 0 | AH22: =AG12+AG17+AG20+AG25+AG29 -> 0 | AI22: =AH22 -> 0
A23: 17 | D23: 1 | F23: =B23*2 -> 0 | G23: =C23*1 -> 0 | H23: =D23*0 -> 0 | I23: =SUM(F23:F23) -> 0 | M23: 17 | O23: 1 | R23: =N23*2 -> 0 | S23: =O23*1 -> 1 | T23: =P23*0 -> 0 | U23: =SUM(R23:R23) -> 0 | Y23: 17 | AB23: 1 | AD23: =Z23*2 -> 0 | AE23: =AA23*1 -> 0 | AF23: =AB23*0 -> 0 | AG23: =SUM(AD23:AD23) -> 0
A24: 18 | B24: 1 | F24: =B24*2 -> 2 | G24: =C24*1 -> 0 | H24: =D24*0 -> 0 | I24: =SUM(F24:F24) -> 2 | M24: 18 | N24: 1 | R24: =N24*2 -> 2 | S24: =O24*1 -> 0 | T24: =P24*0 -> 0 | U24: =SUM(R24:R24) -> 2 | Y24: 18 | AA24: 1 | AD24: =Z24*2 -> 0 | AE24: =AA24*1 -> 1 | AF24: =AB24*0 -> 0 | AG24: =SUM(AD24:AD24) -> 0
A25: 19 | B25: 1 | F25: =B25*0 -> 0 | G25: =C25*1 -> 0 | H25: =D25*2 -> 0 | I25: =SUM(F25:F25) -> 0 | K25: รวมคะแนนสัมพันธภาพทางสังคม 30 คะแนน | M25: 19 | N25: 1 | R25: =N25*0 -> 0 | S25: =O25*1 -> 0 | T25: =P25*2 -> 0 | U25: =SUM(R25:R25) -> 0 | W25: รวมคะแนนสัมพันธภาพทางสังคม 30 คะแนน | Y25: 19 | AA25: 1 | AD25: =Z25*0 -> 0 | AE25: =AA25*1 -> 1 | AF25: =AB25*2 -> 0 | AG25: =SUM(AD25:AD25) -> 0 | AI25: รวมคะแนนสัมพันธภาพทางสังคม 30 คะแนน
A26: 20 | C26: 1 | F26: =B26*0 -> 0 | G26: =C26*1 -> 1 | H26: =D26*2 -> 0 | I26: =SUM(F26:F26) -> 0 | K26: เกณฑ์ 4 - 10 มีจุดแข็ง , 0 - 3 ไม่มีจุดแข็ง | M26: 20 | O26: 1 | R26: =N26*0 -> 0 | S26: =O26*1 -> 1 | T26: =P26*2 -> 0 | U26: =SUM(R26:R26) -> 0 | W26: เกณฑ์ 4 - 10 มีจุดแข็ง , 0 - 3 ไม่มีจุดแข็ง | Y26: 20 | AA26: 1 | AD26: =Z26*0 -> 0 | AE26: =AA26*1 -> 1 | AF26: =AB26*2 -> 0 | AG26: =SUM(AD26:AD26) -> 0 | AI26: เกณฑ์ 4 - 10 มีจุดแข็ง , 0 - 3 ไม่มีจุดแข็ง
A27: 21 | C27: 1 | F27: =B27*0 -> 0 | G27: =C27*1 -> 1 | H27: =D27*2 -> 0 | I27: =SUM(F27:F27) -> 0 | J27: =I7+I10+I15+I23+I26 -> 0 | K27: =J27 -> 0 | M27: 21 | O27: 1 | R27: =N27*0 -> 0 | S27: =O27*1 -> 1 | T27: =P27*2 -> 0 | U27: =SUM(R27:R27) -> 0 | V27: =U7+U10+U15+U23+U26 -> 0 | W27: =V27 -> 0 | Y27: 21 | AA27: 1 | AD27: =Z27*0 -> 0 | AE27: =AA27*1 -> 1 | AF27: =AB27*2 -> 0 | AG27: =SUM(AD27:AD27) -> 0 | AH27: =AG7+AG10+AG15+AG23+AG26 -> 0 | AI27: =AH27 -> 0
A28: 22 | B28: 1 | F28: =B28*0 -> 0 | G28: =C28*1 -> 0 | H28: =D28*2 -> 0 | I28: =SUM(F28:F28) -> 0 | M28: 22 | N28: 1 | R28: =N28*0 -> 0 | S28: =O28*1 -> 0 | T28: =P28*2 -> 0 | U28: =SUM(R28:R28) -> 0 | Y28: 22 | Z28: 1 | AD28: =Z28*0 -> 0 | AE28: =AA28*1 -> 0 | AF28: =AB28*2 -> 0 | AG28: =SUM(AD28:AD28) -> 0
A29: 23 | C29: 1 | F29: =B29*0 -> 0 | G29: =C29*1 -> 1 | H29: =D29*2 -> 0 | I29: =SUM(F29:F29) -> 0 | K29: คะแนนรวมพฤติกรรมที่เป็นปัญหา 4 ด้าน | M29: 23 | O29: 1 | R29: =N29*0 -> 0 | S29: =O29*1 -> 1 | T29: =P29*2 -> 0 | U29: =SUM(R29:R29) -> 0 | W29: คะแนนรวมพฤติกรรมที่เป็นปัญหา 4 ด้าน | Y29: 23 | AA29: 1 | AD29: =Z29*0 -> 0 | AE29: =AA29*1 -> 1 | AF29: =AB29*2 -> 0 | AG29: =SUM(AD29:AD29) -> 0 | AI29: คะแนนรวมพฤติกรรมที่เป็นปัญหา 4 ด้าน
A30: 24 | C30: 1 | F30: =B30*0 -> 0 | G30: =C30*1 -> 1 | H30: =D30*2 -> 0 | I30: =SUM(F30:F30) -> 0 | K30: เกณฑ์ 0 - 16 ปกติ , 17 - 40 เสี่ยง/มีปัญหา/มีปัญหา | M30: 24 | O30: 1 | R30: =N30*0 -> 0 | S30: =O30*1 -> 1 | T30: =P30*2 -> 0 | U30: =SUM(R30:R30) -> 0 | W30: เกณฑ์ 0 - 16 ปกติ , 17 - 40 เสี่ยง/มีปัญหา/มีปัญหา | Y30: 24 | AA30: 1 | AD30: =Z30*0 -> 0 | AE30: =AA30*1 -> 1 | AF30: =AB30*2 -> 0 | AG30: =SUM(AD30:AD30) -> 0 | AI30: เกณฑ์ 0 - 16 ปกติ , 17 - 40 เสี่ยง/มีปัญหา/มีปัญหา
A31: 25 | C31: 1 | F31: =B31*0 -> 0 | G31: =C31*1 -> 1 | H31: =D31*2 -> 0 | I31: =SUM(F31:F31) -> 0 | K31: =K7+K12+K17+K22 -> 4 | M31: 25 | O31: 1 | R31: =N31*0 -> 0 | S31: =O31*1 -> 1 | T31: =P31*2 -> 0 | U31: =SUM(R31:R31) -> 0 | W31: =W7+W12+W17+W22 -> 4 | Y31: 25 | AA31: 1 | AD31: =Z31*0 -> 0 | AE31: =AA31*1 -> 1 | AF31: =AB31*2 -> 0 | AG31: =SUM(AD31:AD31) -> 0 | AI31: =AI7+AI12+AI17+AI22 -> 0
A32: ด้านหลัง | B32: ปัญหาด้านอารมณ์ สมาธิ หรือความสามารถเข้ากับผู้อื่น | M32: ด้านหลัง | N32: ปัญหาด้านอารมณ์ สมาธิ หรือความสามารถเข้ากับผู้อื่น | Y32: ด้านหลัง | Z32: ปัญหาด้านอารมณ์ สมาธิ หรือความสามารถเข้ากับผู้อื่น
A33: ข้อ | B33: ไม่ | C33: เล็กน้อย | D33: ค่อนข้างมาก | E33: มาก | F33: ปัญหาเล็กน้อย | G33: ปัญหาชัดเจน | H33: ปัญหาอย่างมาก | I33: รวม | K33: สรุปการแปลผลด้านหลัง | M33: ข้อ | N33: ไม่ | O33: เล็กน้อย | P33: ค่อนข้างมาก | Q33: มาก | R33: ปัญหาเล็กน้อย | S33: ปัญหาชัดเจน | T33: ปัญหาอย่างมาก | U33: รวม | W33: สรุปการแปลผลด้านหลัง | Y33: ข้อ | Z33: ไม่ | AA33: เล็กน้อย | AB33: ค่อนข้างมาก | AC33: มาก | AD33: ปัญหาเล็กน้อย | AE33: ปัญหาชัดเจน | AF33: ปัญหาอย่างมาก | AG33: รวม | AI33: สรุปการแปลผลด้านหลัง
A34: อารมณ์ | F34: =C34*0 -> 0 | G34: =D34*1 -> 0 | H34: =E34*2 -> 0 | I34: =SUM(F34:F34) -> 0 | K34: เกณฑ์ 0 ปกติ | M34: อารมณ์ | R34: =O34*0 -> 0 | S34: =P34*1 -> 0 | T34: =Q34*2 -> 0 | U34: =SUM(R34:R34) -> 0 | W34: เกณฑ์ 0 ปกติ | Y34: อารมณ์ | AD34: =AA34*0 -> 0 | AE34: =AB34*1 -> 0 | AF34: =AC34*2 -> 0 | AG34: =SUM(AD34:AD34) -> 0 | AI34: เกณฑ์ 0 ปกติ
A35: เวลา | F35: =C35*0 -> 0 | G35: =D35*1 -> 0 | H35: =E35*2 -> 0 | I35: =SUM(F35:F35) -> 0 | J35: =I34+I35+I36+I37+I38+I39+I40+I41 -> 0 | K35: คะแนนรวม 1 คะแนนขึ้นไป เสี่ยง/มีปัญหา | M35: เวลา | R35: =O35*0 -> 0 | S35: =P35*1 -> 0 | T35: =Q35*2 -> 0 | U35: =SUM(R35:R35) -> 0 | V35: =U34+U35+U36+U37+U38+U39+U40+U41 -> 0 | W35: คะแนนรวม 1 คะแนนขึ้นไป เสี่ยง/มีปัญหา | Y35: เวลา | AD35: =AA35*0 -> 0 | AE35: =AB35*1 -> 0 | AF35: =AC35*2 -> 0 | AG35: =SUM(AD35:AD35) -> 0 | AH35: =AG34+AG35+AG36+AG37+AG38+AG39+AG40+AG41 -> 0 | AI35: คะแนนรวม 1 คะแนนขึ้นไป เสี่ยง/มีปัญหา
A36: รู้สึก | F36: =C36*0 -> 0 | G36: =D36*1 -> 0 | H36: =E36*2 -> 0 | I36: =SUM(F36:F36) -> 0 | M36: รู้สึก | R36: =O36*0 -> 0 | S36: =P36*1 -> 0 | T36: =Q36*2 -> 0 | U36: =SUM(R36:R36) -> 0 | Y36: รู้สึก | AD36: =AA36*0 -> 0 | AE36: =AB36*1 -> 0 | AF36: =AC36*2 -> 0 | AG36: =SUM(AD36:AD36) -> 0
A37: ความเป็นอยู่ | F37: =C37*0 -> 0 | G37: =D37*1 -> 0 | H37: =E37*2 -> 0 | I37: =SUM(F37:F37) -> 0 | K37: =J35 -> 0 | M37: ความเป็นอยู่ | R37: =O37*0 -> 0 | S37: =P37*1 -> 0 | T37: =Q37*2 -> 0 | U37: =SUM(R37:R37) -> 0 | W37: =V35 -> 0 | Y37: ความเป็นอยู่ | AD37: =AA37*0 -> 0 | AE37: =AB37*1 -> 0 | AF37: =AC37*2 -> 0 | AG37: =SUM(AD37:AD37) -> 0 | AI37: =AH35 -> 0
A38: การคบเพื่อน | F38: =C38*0 -> 0 | G38: =D38*1 -> 0 | H38: =E38*2 -> 0 | I38: =SUM(F38:F38) -> 0 | M38: การคบเพื่อน | R38: =O38*0 -> 0 | S38: =P38*1 -> 0 | T38: =Q38*2 -> 0 | U38: =SUM(R38:R38) -> 0 | Y38: การคบเพื่อน | AD38: =AA38*0 -> 0 | AE38: =AB38*1 -> 0 | AF38: =AC38*2 -> 0 | AG38: =SUM(AD38:AD38) -> 0
A39: การเรียนในห้องเรียน | F39: =C39*0 -> 0 | G39: =D39*1 -> 0 | H39: =E39*2 -> 0 | I39: =SUM(F39:F39) -> 0 | M39: การเรียนในห้องเรียน | R39: =O39*0 -> 0 | S39: =P39*1 -> 0 | T39: =Q39*2 -> 0 | U39: =SUM(R39:R39) -> 0 | Y39: การเรียนในห้องเรียน | AD39: =AA39*0 -> 0 | AE39: =AB39*1 -> 0 | AF39: =AC39*2 -> 0 | AG39: =SUM(AD39:AD39) -> 0
A40: กิจกรรมยามว่าง | F40: =C40*0 -> 0 | G40: =D40*1 -> 0 | H40: =E40*2 -> 0 | I40: =SUM(F40:F40) -> 0 | M40: กิจกรรมยามว่าง | R40: =O40*0 -> 0 | S40: =P40*1 -> 0 | T40: =Q40*2 -> 0 | U40: =SUM(R40:R40) -> 0 | Y40: กิจกรรมยามว่าง | AD40: =AA40*0 -> 0 | AE40: =AB40*1 -> 0 | AF40: =AC40*2 -> 0 | AG40: =SUM(AD40:AD40) -> 0
...

Sheet 04
A1: ผลการประเมินพฤติกรรมตนเอง (SDQ) | M1: ผลการประเมินพฤติกรรม ครูประเมินนักเรียน (SDQ) | Y1: ผลการประเมินพฤติกรรม ผู้ปกครองประเมินนักเรียน (SDQ)
A2: =ข้อมูล!C7 -> โรงเรียนเทศบาลท่าอิฐ อำเภอเมือง จังหวัดอุตรดิตถ์ | M2: =ข้อมูล!C7 -> โรงเรียนเทศบาลท่าอิฐ อำเภอเมือง จังหวัดอุตรดิตถ์ | Y2: โรงเรียนเทศบาลท่าอิฐ อำเภอเมือง จังหวัดอุตรดิตถ์
A3: ชื่อ-สกุล | B3: =รายชื่อ!B4 -> เด็กชาย | C3: =รายชื่อ!C4 -> ภูมิพัฒน์ | D3: =รายชื่อ!D4 -> เต็งวิลัย | K3: 4 | M3: ชื่อ-สกุล | N3: =รายชื่อ!B4 -> เด็กชาย | O3: =รายชื่อ!C4 -> ภูมิพัฒน์ | P3: =รายชื่อ!D4 -> เต็งวิลัย | W3: 4 | Y3: ชื่อ-สกุล | Z3: =รายชื่อ!B4 -> เด็กชาย | AA3: =รายชื่อ!C4 -> ภูมิพัฒน์ | AB3: =รายชื่อ!D4 -> เต็งวิลัย | AI3: 4
A4: SDQ1 | M4: SDQ2 | Y4: SDQ3
A5: รายการประเมินโดยนักเรียน | F5: คะแนน | K5: รวมคะแนนด้านอารมณ์ 10 คะแนน | M5: รายการประเมินโดยครู | R5: คะแนน | W5: รวมคะแนนด้านอารมณ์ 10 คะแนน | Y5: รายการประเมินโดยผู้ปกครอง | AD5: คะแนน | AI5: รวมคะแนนด้านอารมณ์ 10 คะแนน
A6: ข้อที่ | B6: ไม่จริง | C6: ค่อนข้างจริง | D6: จริง | F6: ไม่จริง | G6: ค่อนข้างจริง | H6: จริง | I6: รวม | K6: เกณฑ์ 0 - 5 ปกติ , 6 - 10 เสี่ยง/มีปัญหา | M6: ข้อที่ | N6: ไม่จริง | O6: ค่อนข้างจริง | P6: จริง | R6: ไม่จริง | S6: ค่อนข้างจริง | T6: จริง | U6: รวม | W6: เกณฑ์ 0 - 5 ปกติ , 6 - 10 เสี่ยง/มีปัญหา | Y6: ข้อที่ | Z6: ไม่จริง | AA6: ค่อนข้างจริง | AB6: จริง | AD6: ไม่จริง | AE6: ค่อนข้างจริง | AF6: จริง | AG6: รวม | AI6: เกณฑ์ 0 - 5 ปกติ , 6 - 10 เสี่ยง/มีปัญหา
A7: 1 | C7: 1 | F7: =B7*0 -> 0 | G7: =C7*1 -> 1 | H7: =D7*2 -> 0 | I7: =SUM(F7:F7) -> 0 | J7: =I9+I14+I19+I22+I30 -> 0 | K7: =J7 -> 0 | M7: 1 | O7: 1 | R7: =N7*0 -> 0 | S7: =O7*1 -> 1 | T7: =P7*2 -> 0 | U7: =SUM(R7:R7) -> 0 | V7: =U9+U14+U19+U22+U30 -> 0 | W7: =V7 -> 0 | Y7: 1 | AA7: 1 | AD7: =Z7*0 -> 0 | AE7: =AA7*1 -> 1 | AF7: =AB7*2 -> 0 | AG7: =SUM(AD7:AD7) -> 0 | AH7: =AG9+AG14+AG19+AG22+AG30 -> 0 | AI7: =AH7 -> 0
A8: 2 | D8: 1 | F8: =B8*0 -> 0 | G8: =C8*1 -> 0 | H8: =D8*2 -> 2 | I8: =SUM(F8:F8) -> 0 | M8: 2 | P8: 1 | R8: =N8*0 -> 0 | S8: =O8*1 -> 0 | T8: =P8*2 -> 2 | U8: =SUM(R8:R8) -> 0 | Y8: 2 | AB8: 1 | AD8: =Z8*0 -> 0 | AE8: =AA8*1 -> 0 | AF8: =AB8*2 -> 2 | AG8: =SUM(AD8:AD8) -> 0
A9: 3 | B9: 1 | F9: =B9*0 -> 0 | G9: =C9*1 -> 0 | H9: =D9*2 -> 0 | I9: =SUM(F9:F9) -> 0 | M9: 3 | O9: 1 | R9: =N9*0 -> 0 | S9: =O9*1 -> 1 | T9: =P9*2 -> 0 | U9: =SUM(R9:R9) -> 0 | Y9: 3 | Z9: 1 | AD9: =Z9*0 -> 0 | AE9: =AA9*1 -> 0 | AF9: =AB9*2 -> 0 | AG9: =SUM(AD9:AD9) -> 0
A10: 4 | D10: 1 | F10: =B10*0 -> 0 | G10: =C10*1 -> 0 | H10: =D10*2 -> 2 | I10: =SUM(F10:F10) -> 0 | K10: รวมคะแนนด้านความประพฤติ/เกเร 10 คะแนน | M10: 4 | O10: 1 | R10: =N10*0 -> 0 | S10: =O10*1 -> 1 | T10: =P10*2 -> 0 | U10: =SUM(R10:R10) -> 0 | W10: รวมคะแนนด้านความประพฤติ/เกเร 10 คะแนน | Y10: 4 | AB10: 1 | AD10: =Z10*0 -> 0 | AE10: =AA10*1 -> 0 | AF10: =AB10*2 -> 2 | AG10: =SUM(AD10:AD10) -> 0 | AI10: รวมคะแนนด้านความประพฤติ/เกเร 10 คะแนน
A11: 5 | B11: 1 | F11: =B11*0 -> 0 | G11: =C11*1 -> 0 | H11: =D11*2 -> 0 | I11: =SUM(F11:F11) -> 0 | K11: เกณฑ์ 0 - 4 ปกติ , 5 - 10 เสี่ยง/มีปัญหา | M11: 5 | N11: 1 | R11: =N11*0 -> 0 | S11: =O11*1 -> 0 | T11: =P11*2 -> 0 | U11: =SUM(R11:R11) -> 0 | W11: เกณฑ์ 0 - 4 ปกติ , 5 - 10 เสี่ยง/มีปัญหา | Y11: 5 | Z11: 1 | AD11: =Z11*0 -> 0 | AE11: =AA11*1 -> 0 | AF11: =AB11*2 -> 0 | AG11: =SUM(AD11:AD11) -> 0 | AI11: เกณฑ์ 0 - 4 ปกติ , 5 - 10 เสี่ยง/มีปัญหา
A12: 6 | B12: 1 | F12: =B12*0 -> 0 | G12: =C12*1 -> 0 | H12: =D12*2 -> 0 | I12: =SUM(F12:F12) -> 0 | J12: =I11+I13+I18+I24+I28 -> 2 | K12: =J12 -> 2 | M12: 6 | O12: 1 | R12: =N12*0 -> 0 | S12: =O12*1 -> 1 | T12: =P12*2 -> 0 | U12: =SUM(R12:R12) -> 0 | V12: =U11+U13+U18+U24+U28 -> 2 | W12: =V12 -> 2 | Y12: 6 | Z12: 1 | AD12: =Z12*0 -> 0 | AE12: =AA12*1 -> 0 | AF12: =AB12*2 -> 0 | AG12: =SUM(AD12:AD12) -> 0 | AH12: =AG11+AG13+AG18+AG24+AG28 -> 2 | AI12: =AH12 -> 2
A13: 7 | C13: 1 | F13: =B13*2 -> 0 | G13: =C13*1 -> 1 | H13: =D13*0 -> 0 | I13: =SUM(F13:F13) -> 0 | M13: 7 | O13: 1 | R13: =N13*2 -> 0 | S13: =O13*1 -> 1 | T13: =P13*0 -> 0 | U13: =SUM(R13:R13) -> 0 | Y13: 7 | AA13: 1 | AD13: =Z13*2 -> 0 | AE13: =AA13*1 -> 1 | AF13: =AB13*0 -> 0 | AG13: =SUM(AD13:AD13) -> 0
A14: 8 | B14: 1 | F14: =B14*0 -> 0 | G14: =C14*1 -> 0 | H14: =D14*2 -> 0 | I14: =SUM(F14:F14) -> 0 | M14: 8 | N14: 1 | R14: =N14*0 -> 0 | S14: =O14*1 -> 0 | T14: =P14*2 -> 0 | U14: =SUM(R14:R14) -> 0 | Y14: 8 | Z14: 1 | AD14: =Z14*0 -> 0 | AE14: =AA14*1 -> 0 | AF14: =AB14*2 -> 0 | AG14: =SUM(AD14:AD14) -> 0
A15: 9 | C15: 1 | F15: =B15*0 -> 0 | G15: =C15*1 -> 1 | H15: =D15*2 -> 0 | I15: =SUM(F15:F15) -> 0 | K15: รวมคะแนนพฤติกรรมอยู่ไม่นิ่ง/สมาธิสั้น 10 คะแนน | M15: 9 | O15: 1 | R15: =N15*0 -> 0 | S15: =O15*1 -> 1 | T15: =P15*2 -> 0 | U15: =SUM(R15:R15) -> 0 | W15: รวมคะแนนพฤติกรรมอยู่ไม่นิ่ง/สมาธิสั้น 10 คะแนน | Y15: 9 | AA15: 1 | AD15: =Z15*0 -> 0 | AE15: =AA15*1 -> 1 | AF15: =AB15*2 -> 0 | AG15: =SUM(AD15:AD15) -> 0 | AI15: รวมคะแนนพฤติกรรมอยู่ไม่นิ่ง/สมาธิสั้น 10 คะแนน
A16: 10 | D16: 1 | F16: =B16*0 -> 0 | G16: =C16*1 -> 0 | H16: =D16*2 -> 2 | I16: =SUM(F16:F16) -> 0 | K16: เกณฑ์ 0 - 5 ปกติ , 6 - 10 เสี่ยง/มีปัญหา | M16: 10 | P16: 1 | R16: =N16*0 -> 0 | S16: =O16*1 -> 0 | T16: =P16*2 -> 2 | U16: =SUM(R16:R16) -> 0 | W16: เกณฑ์ 0 - 5 ปกติ , 6 - 10 เสี่ยง/มีปัญหา | Y16: 10 | AB16: 1 | AD16: =Z16*0 -> 0 | AE16: =AA16*1 -> 0 | AF16: =AB16*2 -> 2 | AG16: =SUM(AD16:AD16) -> 0 | AI16: เกณฑ์ 0 - 5 ปกติ , 6 - 10 เสี่ยง/มีปัญหา
A17: 11 | D17: 1 | F17: =B17*0 -> 0 | G17: =C17*1 -> 0 | H17: =D17*2 -> 2 | I17: =SUM(F17:F17) -> 0 | J17: =I8+I16+I21+I27+I31 -> 0 | K17: =J17 -> 0 | M17: 11 | P17: 1 | R17: =N17*0 -> 0 | S17: =O17*1 -> 0 | T17: =P17*2 -> 2 | U17: =SUM(R17:R17) -> 0 | V17: =U8+U16+U21+U27+U31 -> 0 | W17: =V17 -> 0 | Y17: 11 | AB17: 1 | AD17: =Z17*0 -> 0 | AE17: =AA17*1 -> 0 | AF17: =AB17*2 -> 2 | AG17: =SUM(AD17:AD17) -> 0 | AH17: =AG8+AG16+AG21+AG27+AG31 -> 0 | AI17: =AH17 -> 0
A18: 12 | B18: 1 | F18: =B18*0 -> 0 | G18: =C18*1 -> 0 | H18: =D18*2 -> 0 | I18: =SUM(F18:F18) -> 0 | M18: 12 | O18: 1 | R18: =N18*0 -> 0 | S18: =O18*1 -> 1 | T18: =P18*2 -> 0 | U18: =SUM(R18:R18) -> 0 | Y18: 12 | Z18: 1 | AD18: =Z18*0 -> 0 | AE18: =AA18*1 -> 0 | AF18: =AB18*2 -> 0 | AG18: =SUM(AD18:AD18) -> 0
A19: 13 | B19: 1 | F19: =B19*0 -> 0 | G19: =C19*1 -> 0 | H19: =D19*2 -> 0 | I19: =SUM(F19:F19) -> 0 | M19: 13 | N19: 1 | R19: =N19*0 -> 0 | S19: =O19*1 -> 0 | T19: =P19*2 -> 0 | U19: =SUM(R19:R19) -> 0 | Y19: 13 | Z19: 1 | AD19: =Z19*0 -> 0 | AE19: =AA19*1 -> 0 | AF19: =AB19*2 -> 0 | AG19: =SUM(AD19:AD19) -> 0
A20: 14 | C20: 1 | F20: =B20*2 -> 0 | G20: =C20*1 -> 1 | H20: =D20*0 -> 0 | I20: =SUM(F20:F20) -> 0 | K20: รวมคะแนนด้านความสัมพันธ์กับเพื่อน 10 คะแนน | M20: 14 | O20: 1 | R20: =N20*2 -> 0 | S20: =O20*1 -> 1 | T20: =P20*0 -> 0 | U20: =SUM(R20:R20) -> 0 | W20: รวมคะแนนด้านความสัมพันธ์กับเพื่อน 10 คะแนน | Y20: 14 | AA20: 1 | AD20: =Z20*2 -> 0 | AE20: =AA20*1 -> 1 | AF20: =AB20*0 -> 0 | AG20: =SUM(AD20:AD20) -> 0 | AI20: รวมคะแนนด้านความสัมพันธ์กับเพื่อน 10 คะแนน
A21: 15 | D21: 1 | F21: =B21*2 -> 0 | G21: =C21*1 -> 0 | H21: =D21*0 -> 0 | I21: =SUM(F21:F21) -> 0 | K21: เกณฑ์ 0 - 3 ปกติ , 4 - 10 เสี่ยง/มีปัญหา | M21: 15 | P21: 1 | R21: =N21*2 -> 0 | S21: =O21*1 -> 0 | T21: =P21*0 -> 0 | U21: =SUM(R21:R21) -> 0 | W21: เกณฑ์ 0 - 3 ปกติ , 4 - 10 เสี่ยง/มีปัญหา | Y21: 15 | AB21: 1 | AD21: =Z21*2 -> 0 | AE21: =AA21*1 -> 0 | AF21: =AB21*0 -> 0 | AG21: =SUM(AD21:AD21) -> 0 | AI21: เกณฑ์ 0 - 3 ปกติ , 4 - 10 เสี่ยง/มีปัญหา
A22: 16 | B22: 1 | F22: =B22*0 -> 0 | G22: =C22*1 -> 0 | H22: =D22*2 -> 0 | I22: =SUM(F22:F22) -> 0 | J22: =I12+I17+I20+I25+I29 -> 0 | K22: =J22 -> 0 | M22: 16 | O22: 1 | R22: =N22*0 -> 0 | S22: =O22*1 -> 1 | T22: =P22*2 -> 0 | U22: =SUM(R22:R22) -> 0 | V22: =U12+U17+U20+U25+U29 -> 0 | W22: =V22 -> 0 | Y22: 16 | Z22: 1 | AD22: =Z22*0 -> 0 | AE22: =AA22*1 -> 0 | AF22: =AB22*2 -> 0 | AG22: =SUM(AD22:AD22) -> 0 | AH22: =AG12+AG17+AG20+AG25+AG29 -> 0 | AI22: =AH22 -> 0
A23: 17 | D23: 1 | F23: =B23*2 -> 0 | G23: =C23*1 -> 0 | H23: =D23*0 -> 0 | I23: =SUM(F23:F23) -> 0 | M23: 17 | O23: 1 | R23: =N23*2 -> 0 | S23: =O23*1 -> 1 | T23: =P23*0 -> 0 | U23: =SUM(R23:R23) -> 0 | Y23: 17 | AB23: 1 | AD23: =Z23*2 -> 0 | AE23: =AA23*1 -> 0 | AF23: =AB23*0 -> 0 | AG23: =SUM(AD23:AD23) -> 0
A24: 18 | B24: 1 | F24: =B24*2 -> 2 | G24: =C24*1 -> 0 | H24: =D24*0 -> 0 | I24: =SUM(F24:F24) -> 2 | M24: 18 | N24: 1 | R24: =N24*2 -> 2 | S24: =O24*1 -> 0 | T24: =P24*0 -> 0 | U24: =SUM(R24:R24) -> 2 | Y24: 18 | Z24: 1 | AD24: =Z24*2 -> 2 | AE24: =AA24*1 -> 0 | AF24: =AB24*0 -> 0 | AG24: =SUM(AD24:AD24) -> 2
A25: 19 | B25: 1 | F25: =B25*0 -> 0 | G25: =C25*1 -> 0 | H25: =D25*2 -> 0 | I25: =SUM(F25:F25) -> 0 | K25: รวมคะแนนสัมพันธภาพทางสังคม 30 คะแนน | M25: 19 | N25: 1 | R25: =N25*0 -> 0 | S25: =O25*1 -> 0 | T25: =P25*2 -> 0 | U25: =SUM(R25:R25) -> 0 | W25: รวมคะแนนสัมพันธภาพทางสังคม 30 คะแนน | Y25: 19 | Z25: 1 | AD25: =Z25*0 -> 0 | AE25: =AA25*1 -> 0 | AF25: =AB25*2 -> 0 | AG25: =SUM(AD25:AD25) -> 0 | AI25: รวมคะแนนสัมพันธภาพทางสังคม 30 คะแนน
A26: 20 | C26: 1 | F26: =B26*0 -> 0 | G26: =C26*1 -> 1 | H26: =D26*2 -> 0 | I26: =SUM(F26:F26) -> 0 | K26: เกณฑ์ 4 - 10 มีจุดแข็ง , 0 - 3 ไม่มีจุดแข็ง | M26: 20 | O26: 1 | R26: =N26*0 -> 0 | S26: =O26*1 -> 1 | T26: =P26*2 -> 0 | U26: =SUM(R26:R26) -> 0 | W26: เกณฑ์ 4 - 10 มีจุดแข็ง , 0 - 3 ไม่มีจุดแข็ง | Y26: 20 | AA26: 1 | AD26: =Z26*0 -> 0 | AE26: =AA26*1 -> 1 | AF26: =AB26*2 -> 0 | AG26: =SUM(AD26:AD26) -> 0 | AI26: เกณฑ์ 4 - 10 มีจุดแข็ง , 0 - 3 ไม่มีจุดแข็ง
A27: 21 | B27: 1 | F27: =B27*0 -> 0 | G27: =C27*1 -> 0 | H27: =D27*2 -> 0 | I27: =SUM(F27:F27) -> 0 | J27: =I7+I10+I15+I23+I26 -> 0 | K27: =J27 -> 0 | M27: 21 | N27: 1 | R27: =N27*0 -> 0 | S27: =O27*1 -> 0 | T27: =P27*2 -> 0 | U27: =SUM(R27:R27) -> 0 | V27: =U7+U10+U15+U23+U26 -> 0 | W27: =V27 -> 0 | Y27: 21 | Z27: 1 | AD27: =Z27*0 -> 0 | AE27: =AA27*1 -> 0 | AF27: =AB27*2 -> 0 | AG27: =SUM(AD27:AD27) -> 0 | AH27: =AG7+AG10+AG15+AG23+AG26 -> 0 | AI27: =AH27 -> 0
A28: 22 | B28: 1 | F28: =B28*0 -> 0 | G28: =C28*1 -> 0 | H28: =D28*2 -> 0 | I28: =SUM(F28:F28) -> 0 | M28: 22 | N28: 1 | R28: =N28*0 -> 0 | S28: =O28*1 -> 0 | T28: =P28*2 -> 0 | U28: =SUM(R28:R28) -> 0 | Y28: 22 | Z28: 1 | AD28: =Z28*0 -> 0 | AE28: =AA28*1 -> 0 | AF28: =AB28*2 -> 0 | AG28: =SUM(AD28:AD28) -> 0
A29: 23 | C29: 1 | F29: =B29*0 -> 0 | G29: =C29*1 -> 1 | H29: =D29*2 -> 0 | I29: =SUM(F29:F29) -> 0 | K29: คะแนนรวมพฤติกรรมที่เป็นปัญหา 4 ด้าน | M29: 23 | O29: 1 | R29: =N29*0 -> 0 | S29: =O29*1 -> 1 | T29: =P29*2 -> 0 | U29: =SUM(R29:R29) -> 0 | W29: คะแนนรวมพฤติกรรมที่เป็นปัญหา 4 ด้าน | Y29: 23 | AA29: 1 | AD29: =Z29*0 -> 0 | AE29: =AA29*1 -> 1 | AF29: =AB29*2 -> 0 | AG29: =SUM(AD29:AD29) -> 0 | AI29: คะแนนรวมพฤติกรรมที่เป็นปัญหา 4 ด้าน
A30: 24 | B30: 1 | F30: =B30*0 -> 0 | G30: =C30*1 -> 0 | H30: =D30*2 -> 0 | I30: =SUM(F30:F30) -> 0 | K30: เกณฑ์ 0 - 16 ปกติ , 17 - 40 เสี่ยง/มีปัญหา/มีปัญหา | M30: 24 | N30: 1 | R30: =N30*0 -> 0 | S30: =O30*1 -> 0 | T30: =P30*2 -> 0 | U30: =SUM(R30:R30) -> 0 | W30: เกณฑ์ 0 - 16 ปกติ , 17 - 40 เสี่ยง/มีปัญหา/มีปัญหา | Y30: 24 | Z30: 1 | AD30: =Z30*0 -> 0 | AE30: =AA30*1 -> 0 | AF30: =AB30*2 -> 0 | AG30: =SUM(AD30:AD30) -> 0 | AI30: เกณฑ์ 0 - 16 ปกติ , 17 - 40 เสี่ยง/มีปัญหา/มีปัญหา
A31: 25 | C31: 1 | F31: =B31*0 -> 0 | G31: =C31*1 -> 1 | H31: =D31*2 -> 0 | I31: =SUM(F31:F31) -> 0 | K31: =K7+K12+K17+K22 -> 2 | M31: 25 | N31: 1 | R31: =N31*0 -> 0 | S31: =O31*1 -> 0 | T31: =P31*2 -> 0 | U31: =SUM(R31:R31) -> 0 | W31: =W7+W12+W17+W22 -> 2 | Y31: 25 | AA31: 1 | AD31: =Z31*0 -> 0 | AE31: =AA31*1 -> 1 | AF31: =AB31*2 -> 0 | AG31: =SUM(AD31:AD31) -> 0 | AI31: =AI7+AI12+AI17+AI22 -> 2
A32: ด้านหลัง | B32: ปัญหาด้านอารมณ์ สมาธิ หรือความสามารถเข้ากับผู้อื่น | M32: ด้านหลัง | N32: ปัญหาด้านอารมณ์ สมาธิ หรือความสามารถเข้ากับผู้อื่น | Y32: ด้านหลัง | Z32: ปัญหาด้านอารมณ์ สมาธิ หรือความสามารถเข้ากับผู้อื่น
A33: ข้อ | B33: ไม่ | C33: เล็กน้อย | D33: ค่อนข้างมาก | E33: มาก | F33: ปัญหาเล็กน้อย | G33: ปัญหาชัดเจน | H33: ปัญหาอย่างมาก | I33: รวม | K33: สรุปการแปลผลด้านหลัง | M33: ข้อ | N33: ไม่ | O33: เล็กน้อย | P33: ค่อนข้างมาก | Q33: มาก | R33: ปัญหาเล็กน้อย | S33: ปัญหาชัดเจน | T33: ปัญหาอย่างมาก | U33: รวม | W33: สรุปการแปลผลด้านหลัง | Y33: ข้อ | Z33: ไม่ | AA33: เล็กน้อย | AB33: ค่อนข้างมาก | AC33: มาก | AD33: ปัญหาเล็กน้อย | AE33: ปัญหาชัดเจน | AF33: ปัญหาอย่างมาก | AG33: รวม | AI33: สรุปการแปลผลด้านหลัง
A34: อารมณ์ | F34: =C34*0 -> 0 | G34: =D34*1 -> 0 | H34: =E34*2 -> 0 | I34: =SUM(F34:F34) -> 0 | K34: เกณฑ์ 0 ปกติ | M34: อารมณ์ | R34: =O34*0 -> 0 | S34: =P34*1 -> 0 | T34: =Q34*2 -> 0 | U34: =SUM(R34:R34) -> 0 | W34: เกณฑ์ 0 ปกติ | Y34: อารมณ์ | AD34: =AA34*0 -> 0 | AE34: =AB34*1 -> 0 | AF34: =AC34*2 -> 0 | AG34: =SUM(AD34:AD34) -> 0 | AI34: เกณฑ์ 0 ปกติ
